Workbook

Sheet R5
A2: Durchbiegung | C2: a0 = | D2: =INTERCEPT(D7:D1381,B7:B1381) -> 7.7146832e-06 | G2: Widerstand 101
C3: a1 = | D3: =SLOPE(D7:D1381,B7:B1381) -> 0.0089565236 | H3: -4.7
A5: Zeit | B5: Pos | C5: Kraft | D5: DR / R | E5: DR / R mionus Gerade | G5: Zeit | H5: Zeit (korr) | I5: DR / R | J5: Widerstand
A6: [s] | B6: [mm] | C6: [N] | G6: [s] | H6: [s] | J6: [W]
A7: =Messdaten!B6 -> 0.02 | B7: =Messdaten!C6 -> 0 | C7: =Messdaten!D6 -> 0.011 | D7: =INDIRECT(ADDRESS(ROW($H$6)+MATCH($A7,$H$7:$H$193,1),COLUMN($H7)+1))+(INDIRECT(ADDRESS(ROW($H$6)+MATCH($A7,$H$7:$H$193,1)+1,COLUMN($H7)+1))-INDIRECT(ADDRESS(ROW($H$6)+MATCH($A7,$H$7:$H$193,1),COLUMN($H7)+1)))*($A7-INDIRECT(ADDRESS(ROW($H$6)+MATCH($A7,$H$7:$H$193,1),COLUMN($H7))))/(INDIRECT(ADDRESS(ROW($H$6)+MATCH($A7,$H$7:$H$193,1)+1,COLUMN($H7)))-INDIRECT(ADDRESS(ROW($H$6)+MATCH($A7,$H$7:$H$193,1),COLUMN($H7)))) -> 2.5168886e-06 | E7: =D7-$D$2-$D$3*B7 -> -5.1977946e-06 | G7: =Messdaten!G6 -> 0.161 | H7: =G7+$H$3 -> -4.539 | I7: =(J7-J$7)/J$7 -> 0 | J7: =Messdaten!F5 -> 7246.4194
A8: =Messdaten!B7 -> 0.04 | B8: =Messdaten!C7 -> 0 | C8: =Messdaten!D7 -> 0.011 | D8: =INDIRECT(ADDRESS(ROW($H$6)+MATCH($A8,$H$7:$H$193,1),COLUMN($H8)+1))+(INDIRECT(ADDRESS(ROW($H$6)+MATCH($A8,$H$7:$H$193,1)+1,COLUMN($H8)+1))-INDIRECT(ADDRESS(ROW($H$6)+MATCH($A8,$H$7:$H$193,1),COLUMN($H8)+1)))*($A8-INDIRECT(ADDRESS(ROW($H$6)+MATCH($A8,$H$7:$H$193,1),COLUMN($H8))))/(INDIRECT(ADDRESS(ROW($H$6)+MATCH($A8,$H$7:$H$193,1)+1,COLUMN($H8)))-INDIRECT(ADDRESS(ROW($H$6)+MATCH($A8,$H$7:$H$193,1),COLUMN($H8)))) -> 2.5873323e-06 | E8: =D8-$D$2-$D$3*B8 -> -5.1273508e-06 | G8: =Messdaten!G7 -> 0.333 | H8: =G8+$H$3 -> -4.367 | I8: =(J8-J$7)/J$7 -> 4.6505726e-06 | J8: =Messdaten!F6 -> 7246.4531
A9: =Messdaten!B8 -> 0.06 | B9: =Messdaten!C8 -> 0 | C9: =Messdaten!D8 -> 0.017 | D9: =INDIRECT(ADDRESS(ROW($H$6)+MATCH($A9,$H$7:$H$193,1),COLUMN($H9)+1))+(INDIRECT(ADDRESS(ROW($H$6)+MATCH($A9,$H$7:$H$193,1)+1,COLUMN($H9)+1))-INDIRECT(ADDRESS(ROW($H$6)+MATCH($A9,$H$7:$H$193,1),COLUMN($H9)+1)))*($A9-INDIRECT(ADDRESS(ROW($H$6)+MATCH($A9,$H$7:$H$193,1),COLUMN($H9))))/(INDIRECT(ADDRESS(ROW($H$6)+MATCH($A9,$H$7:$H$193,1)+1,COLUMN($H9)))-INDIRECT(ADDRESS(ROW($H$6)+MATCH($A9,$H$7:$H$193,1),COLUMN($H9)))) -> 2.6577761e-06 | E9: =D9-$D$2-$D$3*B9 -> -5.0569071e-06 | G9: =Messdaten!G8 -> 0.505 | H9: =G9+$H$3 -> -4.195 | I9: =(J9-J$7)/J$7 -> 4.9872907e-06 | J9: =Messdaten!F7 -> 7246.4556
A10: =Messdaten!B9 -> 0.08 | B10: =Messdaten!C9 -> 0 | C10: =Messdaten!D9 -> 0.011 | D10: =INDIRECT(ADDRESS(ROW($H$6)+MATCH($A10,$H$7:$H$193,1),COLUMN($H10)+1))+(INDIRECT(ADDRESS(ROW($H$6)+MATCH($A10,$H$7:$H$193,1)+1,COLUMN($H10)+1))-INDIRECT(ADDRESS(ROW($H$6)+MATCH($A10,$H$7:$H$193,1),COLUMN($H10)+1)))*($A10-INDIRECT(ADDRESS(ROW($H$6)+MATCH($A10,$H$7:$H$193,1),COLUMN($H10))))/(INDIRECT(ADDRESS(ROW($H$6)+MATCH($A10,$H$7:$H$193,1)+1,COLUMN($H10)))-INDIRECT(ADDRESS(ROW($H$6)+MATCH($A10,$H$7:$H$193,1),COLUMN($H10)))) -> 2.7282199e-06 | E10: =D10-$D$2-$D$3*B10 -> -4.9864633e-06 | G10: =Messdaten!G9 -> 0.677 | H10: =G10+$H$3 -> -4.023 | I10: =(J10-J$7)/J$7 -> 4.246235e-06 | J10: =Messdaten!F8 -> 7246.4502
A11: =Messdaten!B10 -> 0.1 | B11: =Messdaten!C10 -> 0 | C11: =Messdaten!D10 -> 0.022 | D11: =INDIRECT(ADDRESS(ROW($H$6)+MATCH($A11,$H$7:$H$193,1),COLUMN($H11)+1))+(INDIRECT(ADDRESS(ROW($H$6)+MATCH($A11,$H$7:$H$193,1)+1,COLUMN($H11)+1))-INDIRECT(ADDRESS(ROW($H$6)+MATCH($A11,$H$7:$H$193,1),COLUMN($H11)+1)))*($A11-INDIRECT(ADDRESS(ROW($H$6)+MATCH($A11,$H$7:$H$193,1),COLUMN($H11))))/(INDIRECT(ADDRESS(ROW($H$6)+MATCH($A11,$H$7:$H$193,1)+1,COLUMN($H11)))-INDIRECT(ADDRESS(ROW($H$6)+MATCH($A11,$H$7:$H$193,1),COLUMN($H11)))) -> 2.7986637e-06 | E11: =D11-$D$2-$D$3*B11 -> -4.9160195e-06 | G11: =Messdaten!G10 -> 0.849 | H11: =G11+$H$3 -> -3.851 | I11: =(J11-J$7)/J$7 -> 4.7844319e-06 | J11: =Messdaten!F9 -> 7246.4541
A12: =Messdaten!B11 -> 0.12 | B12: =Messdaten!C11 -> 0 | C12: =Messdaten!D11 -> 0.017 | D12: =INDIRECT(ADDRESS(ROW($H$6)+MATCH($A12,$H$7:$H$193,1),COLUMN($H12)+1))+(INDIRECT(ADDRESS(ROW($H$6)+MATCH($A12,$H$7:$H$193,1)+1,COLUMN($H12)+1))-INDIRECT(ADDRESS(ROW($H$6)+MATCH($A12,$H$7:$H$193,1),COLUMN($H12)+1)))*($A12-INDIRECT(ADDRESS(ROW($H$6)+MATCH($A12,$H$7:$H$193,1),COLUMN($H12))))/(INDIRECT(ADDRESS(ROW($H$6)+MATCH($A12,$H$7:$H$193,1)+1,COLUMN($H12)))-INDIRECT(ADDRESS(ROW($H$6)+MATCH($A12,$H$7:$H$193,1),COLUMN($H12)))) -> 2.6451155e-06 | E12: =D12-$D$2-$D$3*B12 -> -5.0695677e-06 | G12: =Messdaten!G11 -> 1.022 | H12: =G12+$H$3 -> -3.678 | I12: =(J12-J$7)/J$7 -> 5.7959659e-06 | J12: =Messdaten!F10 -> 7246.4614
A13: =Messdaten!B12 -> 0.14 | B13: =Messdaten!C12 -> 0 | C13: =Messdaten!D12 -> 0.011 | D13: =INDIRECT(ADDRESS(ROW($H$6)+MATCH($A13,$H$7:$H$193,1),COLUMN($H13)+1))+(INDIRECT(ADDRESS(ROW($H$6)+MATCH($A13,$H$7:$H$193,1)+1,COLUMN($H13)+1))-INDIRECT(ADDRESS(ROW($H$6)+MATCH($A13,$H$7:$H$193,1),COLUMN($H13)+1)))*($A13-INDIRECT(ADDRESS(ROW($H$6)+MATCH($A13,$H$7:$H$193,1),COLUMN($H13))))/(INDIRECT(ADDRESS(ROW($H$6)+MATCH($A13,$H$7:$H$193,1)+1,COLUMN($H13)))-INDIRECT(ADDRESS(ROW($H$6)+MATCH($A13,$H$7:$H$193,1),COLUMN($H13)))) -> 2.3083012e-06 | E13: =D13-$D$2-$D$3*B13 -> -5.406382e-06 | G13: =Messdaten!G12 -> 1.194 | H13: =G13+$H$3 -> -3.506 | I13: =(J13-J$7)/J$7 -> 2.2921665e-06 | J13: =Messdaten!F11 -> 7246.436
A14: =Messdaten!B13 -> 0.16 | B14: =Messdaten!C13 -> 0 | C14: =Messdaten!D13 -> 0.011 | D14: =INDIRECT(ADDRESS(ROW($H$6)+MATCH($A14,$H$7:$H$193,1),COLUMN($H14)+1))+(INDIRECT(ADDRESS(ROW($H$6)+MATCH($A14,$H$7:$H$193,1)+1,COLUMN($H14)+1))-INDIRECT(ADDRESS(ROW($H$6)+MATCH($A14,$H$7:$H$193,1),COLUMN($H14)+1)))*($A14-INDIRECT(ADDRESS(ROW($H$6)+MATCH($A14,$H$7:$H$193,1),COLUMN($H14))))/(INDIRECT(ADDRESS(ROW($H$6)+MATCH($A14,$H$7:$H$193,1)+1,COLUMN($H14)))-INDIRECT(ADDRESS(ROW($H$6)+MATCH($A14,$H$7:$H$193,1),COLUMN($H14)))) -> 1.9714869e-06 | E14: =D14-$D$2-$D$3*B14 -> -5.7431963e-06 | G14: =Messdaten!G13 -> 1.366 | H14: =G14+$H$3 -> -3.334 | I14: =(J14-J$7)/J$7 -> 4.1109958e-06 | J14: =Messdaten!F12 -> 7246.4492
A15: =Messdaten!B14 -> 0.18 | B15: =Messdaten!C14 -> 0 | C15: =Messdaten!D14 -> 0.011 | D15: =INDIRECT(ADDRESS(ROW($H$6)+MATCH($A15,$H$7:$H$193,1),COLUMN($H15)+1))+(INDIRECT(ADDRESS(ROW($H$6)+MATCH($A15,$H$7:$H$193,1)+1,COLUMN($H15)+1))-INDIRECT(ADDRESS(ROW($H$6)+MATCH($A15,$H$7:$H$193,1),COLUMN($H15)+1)))*($A15-INDIRECT(ADDRESS(ROW($H$6)+MATCH($A15,$H$7:$H$193,1),COLUMN($H15))))/(INDIRECT(ADDRESS(ROW($H$6)+MATCH($A15,$H$7:$H$193,1)+1,COLUMN($H15)))-INDIRECT(ADDRESS(ROW($H$6)+MATCH($A15,$H$7:$H$193,1),COLUMN($H15)))) -> 1.6346726e-06 | E15: =D15-$D$2-$D$3*B15 -> -6.0800106e-06 | G15: =Messdaten!G14 -> 1.538 | H15: =G15+$H$3 -> -3.162 | I15: =(J15-J$7)/J$7 -> 3.9757566e-06 | J15: =Messdaten!F13 -> 7246.4482
A16: =Messdaten!B15 -> 0.2 | B16: =Messdaten!C15 -> 0 | C16: =Messdaten!D15 -> 0.017 | D16: =INDIRECT(ADDRESS(ROW($H$6)+MATCH($A16,$H$7:$H$193,1),COLUMN($H16)+1))+(INDIRECT(ADDRESS(ROW($H$6)+MATCH($A16,$H$7:$H$193,1)+1,COLUMN($H16)+1))-INDIRECT(ADDRESS(ROW($H$6)+MATCH($A16,$H$7:$H$193,1),COLUMN($H16)+1)))*($A16-INDIRECT(ADDRESS(ROW($H$6)+MATCH($A16,$H$7:$H$193,1),COLUMN($H16))))/(INDIRECT(ADDRESS(ROW($H$6)+MATCH($A16,$H$7:$H$193,1)+1,COLUMN($H16)))-INDIRECT(ADDRESS(ROW($H$6)+MATCH($A16,$H$7:$H$193,1),COLUMN($H16)))) -> 1.2978583e-06 | E16: =D16-$D$2-$D$3*B16 -> -6.4168249e-06 | G16: =Messdaten!G15 -> 1.71 | H16: =G16+$H$3 -> -2.99 | I16: =(J16-J$7)/J$7 -> 6.469402e-06 | J16: =Messdaten!F14 -> 7246.4663
A17: =Messdaten!B16 -> 0.22 | B17: =Messdaten!C16 -> 0 | C17: =Messdaten!D16 -> 0 | D17: =INDIRECT(ADDRESS(ROW($H$6)+MATCH($A17,$H$7:$H$193,1),COLUMN($H17)+1))+(INDIRECT(ADDRESS(ROW($H$6)+MATCH($A17,$H$7:$H$193,1)+1,COLUMN($H17)+1))-INDIRECT(ADDRESS(ROW($H$6)+MATCH($A17,$H$7:$H$193,1),COLUMN($H17)+1)))*($A17-INDIRECT(ADDRESS(ROW($H$6)+MATCH($A17,$H$7:$H$193,1),COLUMN($H17))))/(INDIRECT(ADDRESS(ROW($H$6)+MATCH($A17,$H$7:$H$193,1)+1,COLUMN($H17)))-INDIRECT(ADDRESS(ROW($H$6)+MATCH($A17,$H$7:$H$193,1),COLUMN($H17)))) -> 9.61044e-07 | E17: =D17-$D$2-$D$3*B17 -> -6.7536392e-06 | G17: =Messdaten!G16 -> 1.882 | H17: =G17+$H$3 -> -2.818 | I17: =(J17-J$7)/J$7 -> 4.6505726e-06 | J17: =Messdaten!F15 -> 7246.4531
A18: =Messdaten!B17 -> 0.24 | B18: =Messdaten!C17 -> 0 | C18: =Messdaten!D17 -> 0.011 | D18: =INDIRECT(ADDRESS(ROW($H$6)+MATCH($A18,$H$7:$H$193,1),COLUMN($H18)+1))+(INDIRECT(ADDRESS(ROW($H$6)+MATCH($A18,$H$7:$H$193,1)+1,COLUMN($H18)+1))-INDIRECT(ADDRESS(ROW($H$6)+MATCH($A18,$H$7:$H$193,1),COLUMN($H18)+1)))*($A18-INDIRECT(ADDRESS(ROW($H$6)+MATCH($A18,$H$7:$H$193,1),COLUMN($H18))))/(INDIRECT(ADDRESS(ROW($H$6)+MATCH($A18,$H$7:$H$193,1)+1,COLUMN($H18)))-INDIRECT(ADDRESS(ROW($H$6)+MATCH($A18,$H$7:$H$193,1),COLUMN($H18)))) -> 6.242297e-07 | E18: =D18-$D$2-$D$3*B18 -> -7.0904535e-06 | G18: =Messdaten!G17 -> 2.054 | H18: =G18+$H$3 -> -2.646 | I18: =(J18-J$7)/J$7 -> 3.908137e-06 | J18: =Messdaten!F16 -> 7246.4478
... A189: =Messdaten!B188 -> 3.66 | B189: =Messdaten!C188 -> -0.16983 | C189: =Messdaten!D188 -> -1.161 | D189: =INDIRECT(ADDRESS(ROW($H$6)+MATCH($A189,$H$7:$H$193,1),COLUMN($H189)+1))+(INDIRECT(ADDRESS(ROW($H$6)+MATCH($A189,$H$7:$H$193,1)+1,COLUMN($H189)+1))-INDIRECT(ADDRESS(ROW($H$6)+MATCH($A189,$H$7:$H$193,1),COLUMN($H189)+1)))*($A189-INDIRECT(ADDRESS(ROW($H$6)+MATCH($A189,$H$7:$H$193,1),COLUMN($H189))))/(INDIRECT(ADDRESS(ROW($H$6)+MATCH($A189,$H$7:$H$193,1)+1,COLUMN($H189)))-INDIRECT(ADDRESS(ROW($H$6)+MATCH($A189,$H$7:$H$193,1),COLUMN($H189)))) -> -0.0015030853 | E189: =D189-$D$2-$D$3*B189 -> 1.0286467e-05 | G189: =Messdaten!G188 -> 31.422 | H189: =G189+$H$3 -> 26.722 | I189: =(J189-J$7)/J$7 -> 5.5254875e-06 | J189: =Messdaten!F187 -> 7246.4595
A190: =Messdaten!B189 -> 3.68 | B190: =Messdaten!C189 -> -0.17083 | C190: =Messdaten!D189 -> -1.178 | D190: =INDIRECT(ADDRESS(ROW($H$6)+MATCH($A190,$H$7:$H$193,1),COLUMN($H190)+1))+(INDIRECT(ADDRESS(ROW($H$6)+MATCH($A190,$H$7:$H$193,1)+1,COLUMN($H190)+1))-INDIRECT(ADDRESS(ROW($H$6)+MATCH($A190,$H$7:$H$193,1),COLUMN($H190)+1)))*($A190-INDIRECT(ADDRESS(ROW($H$6)+MATCH($A190,$H$7:$H$193,1),COLUMN($H190))))/(INDIRECT(ADDRESS(ROW($H$6)+MATCH($A190,$H$7:$H$193,1)+1,COLUMN($H190)))-INDIRECT(ADDRESS(ROW($H$6)+MATCH($A190,$H$7:$H$193,1),COLUMN($H190)))) -> -0.0015117746 | E190: =D190-$D$2-$D$3*B190 -> 1.0553695e-05
A191: =Messdaten!B190 -> 3.7 | B191: =Messdaten!C190 -> -0.17184 | C191: =Messdaten!D190 -> -1.184 | D191: =INDIRECT(ADDRESS(ROW($H$6)+MATCH($A191,$H$7:$H$193,1),COLUMN($H191)+1))+(INDIRECT(ADDRESS(ROW($H$6)+MATCH($A191,$H$7:$H$193,1)+1,COLUMN($H191)+1))-INDIRECT(ADDRESS(ROW($H$6)+MATCH($A191,$H$7:$H$193,1),COLUMN($H191)+1)))*($A191-INDIRECT(ADDRESS(ROW($H$6)+MATCH($A191,$H$7:$H$193,1),COLUMN($H191))))/(INDIRECT(ADDRESS(ROW($H$6)+MATCH($A191,$H$7:$H$193,1)+1,COLUMN($H191)))-INDIRECT(ADDRESS(ROW($H$6)+MATCH($A191,$H$7:$H$193,1),COLUMN($H191)))) -> -0.0015204638 | E191: =D191-$D$2-$D$3*B191 -> 1.0910489e-05
A192: =Messdaten!B191 -> 3.72 | B192: =Messdaten!C191 -> -0.17288 | C192: =Messdaten!D191 -> -1.184 | D192: =INDIRECT(ADDRESS(ROW($H$6)+MATCH($A192,$H$7:$H$193,1),COLUMN($H192)+1))+(INDIRECT(ADDRESS(ROW($H$6)+MATCH($A192,$H$7:$H$193,1)+1,COLUMN($H192)+1))-INDIRECT(ADDRESS(ROW($H$6)+MATCH($A192,$H$7:$H$193,1),COLUMN($H192)+1)))*($A192-INDIRECT(ADDRESS(ROW($H$6)+MATCH($A192,$H$7:$H$193,1),COLUMN($H192))))/(INDIRECT(ADDRESS(ROW($H$6)+MATCH($A192,$H$7:$H$193,1)+1,COLUMN($H192)))-INDIRECT(ADDRESS(ROW($H$6)+MATCH($A192,$H$7:$H$193,1),COLUMN($H192)))) -> -0.0015291531 | E192: =D192-$D$2-$D$3*B192 -> 1.1535978e-05
A193: =Messdaten!B192 -> 3.74 | B193: =Messdaten!C192 -> -0.17384 | C193: =Messdaten!D192 -> -1.195 | D193: =INDIRECT(ADDRESS(ROW($H$6)+MATCH($A193,$H$7:$H$193,1),COLUMN($H193)+1))+(INDIRECT(ADDRESS(ROW($H$6)+MATCH($A193,$H$7:$H$193,1)+1,COLUMN($H193)+1))-INDIRECT(ADDRESS(ROW($H$6)+MATCH($A193,$H$7:$H$193,1),COLUMN($H193)+1)))*($A193-INDIRECT(ADDRESS(ROW($H$6)+MATCH($A193,$H$7:$H$193,1),COLUMN($H193))))/(INDIRECT(ADDRESS(ROW($H$6)+MATCH($A193,$H$7:$H$193,1)+1,COLUMN($H193)))-INDIRECT(ADDRESS(ROW($H$6)+MATCH($A193,$H$7:$H$193,1),COLUMN($H193)))) -> -0.001538202 | E193: =D193-$D$2-$D$3*B193 -> 1.1085409e-05
A194: =Messdaten!B193 -> 3.76 | B194: =Messdaten!C193 -> -0.17485 | C194: =Messdaten!D193 -> -1.2 | D194: =INDIRECT(ADDRESS(ROW($H$6)+MATCH($A194,$H$7:$H$193,1),COLUMN($H194)+1))+(INDIRECT(ADDRESS(ROW($H$6)+MATCH($A194,$H$7:$H$193,1)+1,COLUMN($H194)+1))-INDIRECT(ADDRESS(ROW($H$6)+MATCH($A194,$H$7:$H$193,1),COLUMN($H194)+1)))*($A194-INDIRECT(ADDRESS(ROW($H$6)+MATCH($A194,$H$7:$H$193,1),COLUMN($H194))))/(INDIRECT(ADDRESS(ROW($H$6)+MATCH($A194,$H$7:$H$193,1)+1,COLUMN($H194)))-INDIRECT(ADDRESS(ROW($H$6)+MATCH($A194,$H$7:$H$193,1),COLUMN($H194)))) -> -0.0015473143 | E194: =D194-$D$2-$D$3*B194 -> 1.1019219e-05
A195: =Messdaten!B194 -> 3.78 | B195: =Messdaten!C194 -> -0.17589 | C195: =Messdaten!D194 -> -1.212 | D195: =INDIRECT(ADDRESS(ROW($H$6)+MATCH($A195,$H$7:$H$193,1),COLUMN($H195)+1))+(INDIRECT(ADDRESS(ROW($H$6)+MATCH($A195,$H$7:$H$193,1)+1,COLUMN($H195)+1))-INDIRECT(ADDRESS(ROW($H$6)+MATCH($A195,$H$7:$H$193,1),COLUMN($H195)+1)))*($A195-INDIRECT(ADDRESS(ROW($H$6)+MATCH($A195,$H$7:$H$193,1),COLUMN($H195))))/(INDIRECT(ADDRESS(ROW($H$6)+MATCH($A195,$H$7:$H$193,1)+1,COLUMN($H195)))-INDIRECT(ADDRESS(ROW($H$6)+MATCH($A195,$H$7:$H$193,1),COLUMN($H195)))) -> -0.0015564265 | E195: =D195-$D$2-$D$3*B195 -> 1.1221724e-05
A196: =Messdaten!B195 -> 3.8 | B196: =Messdaten!C195 -> -0.17689 | C196: =Messdaten!D195 -> -1.212 | D196: =INDIRECT(ADDRESS(ROW($H$6)+MATCH($A196,$H$7:$H$193,1),COLUMN($H196)+1))+(INDIRECT(ADDRESS(ROW($H$6)+MATCH($A196,$H$7:$H$193,1)+1,COLUMN($H196)+1))-INDIRECT(ADDRESS(ROW($H$6)+MATCH($A196,$H$7:$H$193,1),COLUMN($H196)+1)))*($A196-INDIRECT(ADDRESS(ROW($H$6)+MATCH($A196,$H$7:$H$193,1),COLUMN($H196))))/(INDIRECT(ADDRESS(ROW($H$6)+MATCH($A196,$H$7:$H$193,1)+1,COLUMN($H196)))-INDIRECT(ADDRESS(ROW($H$6)+MATCH($A196,$H$7:$H$193,1),COLUMN($H196)))) -> -0.0015655388 | E196: =D196-$D$2-$D$3*B196 -> 1.1065969e-05
A197: =Messdaten!B196 -> 3.82 | B197: =Messdaten!C196 -> -0.17789 | C197: =Messdaten!D196 -> -1.228 | D197: =INDIRECT(ADDRESS(ROW($H$6)+MATCH($A197,$H$7:$H$193,1),COLUMN($H197)+1))+(INDIRECT(ADDRESS(ROW($H$6)+MATCH($A197,$H$7:$H$193,1)+1,COLUMN($H197)+1))-INDIRECT(ADDRESS(ROW($H$6)+MATCH($A197,$H$7:$H$193,1),COLUMN($H197)+1)))*($A197-INDIRECT(ADDRESS(ROW($H$6)+MATCH($A197,$H$7:$H$193,1),COLUMN($H197))))/(INDIRECT(ADDRESS(ROW($H$6)+MATCH($A197,$H$7:$H$193,1)+1,COLUMN($H197)))-INDIRECT(ADDRESS(ROW($H$6)+MATCH($A197,$H$7:$H$193,1),COLUMN($H197)))) -> -0.0015746511 | E197: =D197-$D$2-$D$3*B197 -> 1.0910214e-05
A198: =Messdaten!B197 -> 3.84 | B198: =Messdaten!C197 -> -0.17886 | C198: =Messdaten!D197 -> -1.234 | D198: =INDIRECT(ADDRESS(ROW($H$6)+MATCH($A198,$H$7:$H$193,1),COLUMN($H198)+1))+(INDIRECT(ADDRESS(ROW($H$6)+MATCH($A198,$H$7:$H$193,1)+1,COLUMN($H198)+1))-INDIRECT(ADDRESS(ROW($H$6)+MATCH($A198,$H$7:$H$193,1),COLUMN($H198)+1)))*($A198-INDIRECT(ADDRESS(ROW($H$6)+MATCH($A198,$H$7:$H$193,1),COLUMN($H198))))/(INDIRECT(ADDRESS(ROW($H$6)+MATCH($A198,$H$7:$H$193,1)+1,COLUMN($H198)))-INDIRECT(ADDRESS(ROW($H$6)+MATCH($A198,$H$7:$H$193,1),COLUMN($H198)))) -> -0.0015837634 | E198: =D198-$D$2-$D$3*B198 -> 1.0485763e-05
A199: =Messdaten!B198 -> 3.86 | B199: =Messdaten!C198 -> -0.1799 | C199: =Messdaten!D198 -> -1.234 | D199: =INDIRECT(ADDRESS(ROW($H$6)+MATCH($A199,$H$7:$H$193,1),COLUMN($H199)+1))+(INDIRECT(ADDRESS(ROW($H$6)+MATCH($A199,$H$7:$H$193,1)+1,COLUMN($H199)+1))-INDIRECT(ADDRESS(ROW($H$6)+MATCH($A199,$H$7:$H$193,1),COLUMN($H199)+1)))*($A199-INDIRECT(ADDRESS(ROW($H$6)+MATCH($A199,$H$7:$H$193,1),COLUMN($H199))))/(INDIRECT(ADDRESS(ROW($H$6)+MATCH($A199,$H$7:$H$193,1)+1,COLUMN($H199)))-INDIRECT(ADDRESS(ROW($H$6)+MATCH($A199,$H$7:$H$193,1),COLUMN($H199)))) -> -0.0015928756 | E199: =D199-$D$2-$D$3*B199 -> 1.0688268e-05
A200: =Messdaten!B199 -> 3.88 | B200: =Messdaten!C199 -> -0.18086 | C200: =Messdaten!D199 -> -1.251 | D200: =INDIRECT(ADDRESS(ROW($H$6)+MATCH($A200,$H$7:$H$193,1),COLUMN($H200)+1))+(INDIRECT(ADDRESS(ROW($H$6)+MATCH($A200,$H$7:$H$193,1)+1,COLUMN($H200)+1))-INDIRECT(ADDRESS(ROW($H$6)+MATCH($A200,$H$7:$H$193,1),COLUMN($H200)+1)))*($A200-INDIRECT(ADDRESS(ROW($H$6)+MATCH($A200,$H$7:$H$193,1),COLUMN($H200))))/(INDIRECT(ADDRESS(ROW($H$6)+MATCH($A200,$H$7:$H$193,1)+1,COLUMN($H200)))-INDIRECT(ADDRESS(ROW($H$6)+MATCH($A200,$H$7:$H$193,1),COLUMN($H200)))) -> -0.0016019879 | E200: =D200-$D$2-$D$3*B200 -> 1.0174252e-05
A201: =Messdaten!B200 -> 3.9 | B201: =Messdaten!C200 -> -0.18183 | C201: =Messdaten!D200 -> -1.234 | D201: =INDIRECT(ADDRESS(ROW($H$6)+MATCH($A201,$H$7:$H$193,1),COLUMN($H201)+1))+(INDIRECT(ADDRESS(ROW($H$6)+MATCH($A201,$H$7:$H$193,1)+1,COLUMN($H201)+1))-INDIRECT(ADDRESS(ROW($H$6)+MATCH($A201,$H$7:$H$193,1),COLUMN($H201)+1)))*($A201-INDIRECT(ADDRESS(ROW($H$6)+MATCH($A201,$H$7:$H$193,1),COLUMN($H201))))/(INDIRECT(ADDRESS(ROW($H$6)+MATCH($A201,$H$7:$H$193,1)+1,COLUMN($H201)))-INDIRECT(ADDRESS(ROW($H$6)+MATCH($A201,$H$7:$H$193,1),COLUMN($H201)))) -> -0.0016110831 | E201: =D201-$D$2-$D$3*B201 -> 9.7668777e-06
... A1381: =Messdaten!B1380 -> 27.5 | B1381: =Messdaten!C1380 -> 0 | C1381: =Messdaten!D1380 -> 0.005 | D1381: =INDIRECT(ADDRESS(ROW($H$6)+MATCH($A1381,$H$7:$H$193,1),COLUMN($H1381)+1))+(INDIRECT(ADDRESS(ROW($H$6)+MATCH($A1381,$H$7:$H$193,1)+1,COLUMN($H1381)+1))-INDIRECT(ADDRESS(ROW($H$6)+MATCH($A1381,$H$7:$H$193,1),COLUMN($H1381)+1)))*($A1381-INDIRECT(ADDRESS(ROW($H$6)+MATCH($A1381,$H$7:$H$193,1),COLUMN($H1381))))/(INDIRECT(ADDRESS(ROW($H$6)+MATCH($A1381,$H$7:$H$193,1)+1,COLUMN($H1381)))-INDIRECT(ADDRESS(ROW($H$6)+MATCH($A1381,$H$7:$H$193,1),COLUMN($H1381)))) -> 5.6863598e-06 | E1381: =D1381-$D$2-$D$3*B1381 -> -2.0283234e-06

Sheet R4
A2: Durchbiegung | C2: a0 = | D2: =INTERCEPT(D7:D1381,B7:B1381) -> 1.117523e-05 | G2: Widerstand 101
C3: a1 = | D3: =SLOPE(D7:D1381,B7:B1381) -> 0.013154618 | H3: -4.53
A5: Zeit | B5: Pos | C5: Kraft | D5: DR / R | E5: DR / R mionus Gerade | G5: Zeit | H5: Zeit (korr) | I5: DR / R | J5: Widerstand
A6: [s] | B6: [mm] | C6: [N] | G6: [s] | H6: [s] | J6: [W]
A7: =Messdaten!B6 -> 0.02 | B7: =Messdaten!C6 -> 0 | C7: =Messdaten!D6 -> 0.011 | D7: =INDIRECT(ADDRESS(ROW($H$6)+MATCH($A7,$H$7:$H$193,1),COLUMN($H7)+1))+(INDIRECT(ADDRESS(ROW($H$6)+MATCH($A7,$H$7:$H$193,1)+1,COLUMN($H7)+1))-INDIRECT(ADDRESS(ROW($H$6)+MATCH($A7,$H$7:$H$193,1),COLUMN($H7)+1)))*($A7-INDIRECT(ADDRESS(ROW($H$6)+MATCH($A7,$H$7:$H$193,1),COLUMN($H7))))/(INDIRECT(ADDRESS(ROW($H$6)+MATCH($A7,$H$7:$H$193,1)+1,COLUMN($H7)))-INDIRECT(ADDRESS(ROW($H$6)+MATCH($A7,$H$7:$H$193,1),COLUMN($H7)))) -> 1.9662474e-06 | E7: =D7-$D$2-$D$3*B7 -> -9.2089825e-06 | G7: =Messdaten!J5 -> 0.037 | H7: =G7+$H$3 -> -4.493 | I7: =(J7-J$7)/J$7 -> 0 | J7: =Messdaten!I5 -> 7357.895
A8: =Messdaten!B7 -> 0.04 | B8: =Messdaten!C7 -> 0 | C8: =Messdaten!D7 -> 0.011 | D8: =INDIRECT(ADDRESS(ROW($H$6)+MATCH($A8,$H$7:$H$193,1),COLUMN($H8)+1))+(INDIRECT(ADDRESS(ROW($H$6)+MATCH($A8,$H$7:$H$193,1)+1,COLUMN($H8)+1))-INDIRECT(ADDRESS(ROW($H$6)+MATCH($A8,$H$7:$H$193,1),COLUMN($H8)+1)))*($A8-INDIRECT(ADDRESS(ROW($H$6)+MATCH($A8,$H$7:$H$193,1),COLUMN($H8))))/(INDIRECT(ADDRESS(ROW($H$6)+MATCH($A8,$H$7:$H$193,1)+1,COLUMN($H8)))-INDIRECT(ADDRESS(ROW($H$6)+MATCH($A8,$H$7:$H$193,1),COLUMN($H8)))) -> 1.7965199e-06 | E8: =D8-$D$2-$D$3*B8 -> -9.37871e-06 | G8: =Messdaten!J6 -> 0.204 | H8: =G8+$H$3 -> -4.326 | I8: =(J8-J$7)/J$7 -> 1.3278254e-06 | J8: =Messdaten!I6 -> 7357.9048
A9: =Messdaten!B8 -> 0.06 | B9: =Messdaten!C8 -> 0 | C9: =Messdaten!D8 -> 0.017 | D9: =INDIRECT(ADDRESS(ROW($H$6)+MATCH($A9,$H$7:$H$193,1),COLUMN($H9)+1))+(INDIRECT(ADDRESS(ROW($H$6)+MATCH($A9,$H$7:$H$193,1)+1,COLUMN($H9)+1))-INDIRECT(ADDRESS(ROW($H$6)+MATCH($A9,$H$7:$H$193,1),COLUMN($H9)+1)))*($A9-INDIRECT(ADDRESS(ROW($H$6)+MATCH($A9,$H$7:$H$193,1),COLUMN($H9))))/(INDIRECT(ADDRESS(ROW($H$6)+MATCH($A9,$H$7:$H$193,1)+1,COLUMN($H9)))-INDIRECT(ADDRESS(ROW($H$6)+MATCH($A9,$H$7:$H$193,1),COLUMN($H9)))) -> 1.6267924e-06 | E9: =D9-$D$2-$D$3*B9 -> -9.5484375e-06 | G9: =Messdaten!J7 -> 0.376 | H9: =G9+$H$3 -> -4.154 | I9: =(J9-J$7)/J$7 -> 6.6323316e-07 | J9: =Messdaten!I7 -> 7357.8999
A10: =Messdaten!B9 -> 0.08 | B10: =Messdaten!C9 -> 0 | C10: =Messdaten!D9 -> 0.011 | D10: =INDIRECT(ADDRESS(ROW($H$6)+MATCH($A10,$H$7:$H$193,1),COLUMN($H10)+1))+(INDIRECT(ADDRESS(ROW($H$6)+MATCH($A10,$H$7:$H$193,1)+1,COLUMN($H10)+1))-INDIRECT(ADDRESS(ROW($H$6)+MATCH($A10,$H$7:$H$193,1),COLUMN($H10)+1)))*($A10-INDIRECT(ADDRESS(ROW($H$6)+MATCH($A10,$H$7:$H$193,1),COLUMN($H10))))/(INDIRECT(ADDRESS(ROW($H$6)+MATCH($A10,$H$7:$H$193,1)+1,COLUMN($H10)))-INDIRECT(ADDRESS(ROW($H$6)+MATCH($A10,$H$7:$H$193,1),COLUMN($H10)))) -> 1.4570649e-06 | E10: =D10-$D$2-$D$3*B10 -> -9.718165e-06 | G10: =Messdaten!J8 -> 0.548 | H10: =G10+$H$3 -> -3.982 | I10: =(J10-J$7)/J$7 -> -7.298283e-07 | J10: =Messdaten!I8 -> 7357.8897
A11: =Messdaten!B10 -> 0.1 | B11: =Messdaten!C10 -> 0 | C11: =Messdaten!D10 -> 0.022 | D11: =INDIRECT(ADDRESS(ROW($H$6)+MATCH($A11,$H$7:$H$193,1),COLUMN($H11)+1))+(INDIRECT(ADDRESS(ROW($H$6)+MATCH($A11,$H$7:$H$193,1)+1,COLUMN($H11)+1))-INDIRECT(ADDRESS(ROW($H$6)+MATCH($A11,$H$7:$H$193,1),COLUMN($H11)+1)))*($A11-INDIRECT(ADDRESS(ROW($H$6)+MATCH($A11,$H$7:$H$193,1),COLUMN($H11))))/(INDIRECT(ADDRESS(ROW($H$6)+MATCH($A11,$H$7:$H$193,1)+1,COLUMN($H11)))-INDIRECT(ADDRESS(ROW($H$6)+MATCH($A11,$H$7:$H$193,1),COLUMN($H11)))) -> 1.2873373e-06 | E11: =D11-$D$2-$D$3*B11 -> -9.8878925e-06 | G11: =Messdaten!J9 -> 0.72 | H11: =G11+$H$3 -> -3.81 | I11: =(J11-J$7)/J$7 -> 7.9642343e-07 | J11: =Messdaten!I9 -> 7357.9009
A12: =Messdaten!B11 -> 0.12 | B12: =Messdaten!C11 -> 0 | C12: =Messdaten!D11 -> 0.017 | D12: =INDIRECT(ADDRESS(ROW($H$6)+MATCH($A12,$H$7:$H$193,1),COLUMN($H12)+1))+(INDIRECT(ADDRESS(ROW($H$6)+MATCH($A12,$H$7:$H$193,1)+1,COLUMN($H12)+1))-INDIRECT(ADDRESS(ROW($H$6)+MATCH($A12,$H$7:$H$193,1),COLUMN($H12)+1)))*($A12-INDIRECT(ADDRESS(ROW($H$6)+MATCH($A12,$H$7:$H$193,1),COLUMN($H12))))/(INDIRECT(ADDRESS(ROW($H$6)+MATCH($A12,$H$7:$H$193,1)+1,COLUMN($H12)))-INDIRECT(ADDRESS(ROW($H$6)+MATCH($A12,$H$7:$H$193,1),COLUMN($H12)))) -> 1.1176098e-06 | E12: =D12-$D$2-$D$3*B12 -> -1.005762e-05 | G12: =Messdaten!J10 -> 0.892 | H12: =G12+$H$3 -> -3.638 | I12: =(J12-J$7)/J$7 -> 1.3278254e-06 | J12: =Messdaten!I10 -> 7357.9048
A13: =Messdaten!B12 -> 0.14 | B13: =Messdaten!C12 -> 0 | C13: =Messdaten!D12 -> 0.011 | D13: =INDIRECT(ADDRESS(ROW($H$6)+MATCH($A13,$H$7:$H$193,1),COLUMN($H13)+1))+(INDIRECT(ADDRESS(ROW($H$6)+MATCH($A13,$H$7:$H$193,1)+1,COLUMN($H13)+1))-INDIRECT(ADDRESS(ROW($H$6)+MATCH($A13,$H$7:$H$193,1),COLUMN($H13)+1)))*($A13-INDIRECT(ADDRESS(ROW($H$6)+MATCH($A13,$H$7:$H$193,1),COLUMN($H13))))/(INDIRECT(ADDRESS(ROW($H$6)+MATCH($A13,$H$7:$H$193,1)+1,COLUMN($H13)))-INDIRECT(ADDRESS(ROW($H$6)+MATCH($A13,$H$7:$H$193,1),COLUMN($H13)))) -> 9.4788232e-07 | E13: =D13-$D$2-$D$3*B13 -> -1.0227348e-05 | G13: =Messdaten!J11 -> 1.065 | H13: =G13+$H$3 -> -3.465 | I13: =(J13-J$7)/J$7 -> 1.8578683e-06 | J13: =Messdaten!I11 -> 7357.9087
A14: =Messdaten!B13 -> 0.16 | B14: =Messdaten!C13 -> 0 | C14: =Messdaten!D13 -> 0.011 | D14: =INDIRECT(ADDRESS(ROW($H$6)+MATCH($A14,$H$7:$H$193,1),COLUMN($H14)+1))+(INDIRECT(ADDRESS(ROW($H$6)+MATCH($A14,$H$7:$H$193,1)+1,COLUMN($H14)+1))-INDIRECT(ADDRESS(ROW($H$6)+MATCH($A14,$H$7:$H$193,1),COLUMN($H14)+1)))*($A14-INDIRECT(ADDRESS(ROW($H$6)+MATCH($A14,$H$7:$H$193,1),COLUMN($H14))))/(INDIRECT(ADDRESS(ROW($H$6)+MATCH($A14,$H$7:$H$193,1)+1,COLUMN($H14)))-INDIRECT(ADDRESS(ROW($H$6)+MATCH($A14,$H$7:$H$193,1),COLUMN($H14)))) -> -3.5952522e-08 | E14: =D14-$D$2-$D$3*B14 -> -1.1211182e-05 | G14: =Messdaten!J12 -> 1.237 | H14: =G14+$H$3 -> -3.293 | I14: =(J14-J$7)/J$7 -> 2.6502145e-07 | J14: =Messdaten!I12 -> 7357.897
A15: =Messdaten!B14 -> 0.18 | B15: =Messdaten!C14 -> 0 | C15: =Messdaten!D14 -> 0.011 | D15: =INDIRECT(ADDRESS(ROW($H$6)+MATCH($A15,$H$7:$H$193,1),COLUMN($H15)+1))+(INDIRECT(ADDRESS(ROW($H$6)+MATCH($A15,$H$7:$H$193,1)+1,COLUMN($H15)+1))-INDIRECT(ADDRESS(ROW($H$6)+MATCH($A15,$H$7:$H$193,1),COLUMN($H15)+1)))*($A15-INDIRECT(ADDRESS(ROW($H$6)+MATCH($A15,$H$7:$H$193,1),COLUMN($H15))))/(INDIRECT(ADDRESS(ROW($H$6)+MATCH($A15,$H$7:$H$193,1)+1,COLUMN($H15)))-INDIRECT(ADDRESS(ROW($H$6)+MATCH($A15,$H$7:$H$193,1),COLUMN($H15)))) -> -1.8338947e-06 | E15: =D15-$D$2-$D$3*B15 -> -1.3009125e-05 | G15: =Messdaten!J13 -> 1.409 | H15: =G15+$H$3 -> -3.121 | I15: =(J15-J$7)/J$7 -> 7.298283e-07 | J15: =Messdaten!I13 -> 7357.9004
A16: =Messdaten!B15 -> 0.2 | B16: =Messdaten!C15 -> 0 | C16: =Messdaten!D15 -> 0.017 | D16: =INDIRECT(ADDRESS(ROW($H$6)+MATCH($A16,$H$7:$H$193,1),COLUMN($H16)+1))+(INDIRECT(ADDRESS(ROW($H$6)+MATCH($A16,$H$7:$H$193,1)+1,COLUMN($H16)+1))-INDIRECT(ADDRESS(ROW($H$6)+MATCH($A16,$H$7:$H$193,1),COLUMN($H16)+1)))*($A16-INDIRECT(ADDRESS(ROW($H$6)+MATCH($A16,$H$7:$H$193,1),COLUMN($H16))))/(INDIRECT(ADDRESS(ROW($H$6)+MATCH($A16,$H$7:$H$193,1)+1,COLUMN($H16)))-INDIRECT(ADDRESS(ROW($H$6)+MATCH($A16,$H$7:$H$193,1),COLUMN($H16)))) -> -3.6318369e-06 | E16: =D16-$D$2-$D$3*B16 -> -1.4807067e-05 | G16: =Messdaten!J14 -> 1.581 | H16: =G16+$H$3 -> -2.949 | I16: =(J16-J$7)/J$7 -> 1.724678e-06 | J16: =Messdaten!I14 -> 7357.9077
A17: =Messdaten!B16 -> 0.22 | B17: =Messdaten!C16 -> 0 | C17: =Messdaten!D16 -> 0 | D17: =INDIRECT(ADDRESS(ROW($H$6)+MATCH($A17,$H$7:$H$193,1),COLUMN($H17)+1))+(INDIRECT(ADDRESS(ROW($H$6)+MATCH($A17,$H$7:$H$193,1)+1,COLUMN($H17)+1))-INDIRECT(ADDRESS(ROW($H$6)+MATCH($A17,$H$7:$H$193,1),COLUMN($H17)+1)))*($A17-INDIRECT(ADDRESS(ROW($H$6)+MATCH($A17,$H$7:$H$193,1),COLUMN($H17))))/(INDIRECT(ADDRESS(ROW($H$6)+MATCH($A17,$H$7:$H$193,1)+1,COLUMN($H17)))-INDIRECT(ADDRESS(ROW($H$6)+MATCH($A17,$H$7:$H$193,1),COLUMN($H17)))) -> -5.429779e-06 | E17: =D17-$D$2-$D$3*B17 -> -1.6605009e-05 | G17: =Messdaten!J15 -> 1.753 | H17: =G17+$H$3 -> -2.777 | I17: =(J17-J$7)/J$7 -> 7.298283e-07 | J17: =Messdaten!I15 -> 7357.9004
A18: =Messdaten!B17 -> 0.24 | B18: =Messdaten!C17 -> 0 | C18: =Messdaten!D17 -> 0.011 | D18: =INDIRECT(ADDRESS(ROW($H$6)+MATCH($A18,$H$7:$H$193,1),COLUMN($H18)+1))+(INDIRECT(ADDRESS(ROW($H$6)+MATCH($A18,$H$7:$H$193,1)+1,COLUMN($H18)+1))-INDIRECT(ADDRESS(ROW($H$6)+MATCH($A18,$H$7:$H$193,1),COLUMN($H18)+1)))*($A18-INDIRECT(ADDRESS(ROW($H$6)+MATCH($A18,$H$7:$H$193,1),COLUMN($H18))))/(INDIRECT(ADDRESS(ROW($H$6)+MATCH($A18,$H$7:$H$193,1)+1,COLUMN($H18)))-INDIRECT(ADDRESS(ROW($H$6)+MATCH($A18,$H$7:$H$193,1),COLUMN($H18)))) -> -7.2277212e-06 | E18: =D18-$D$2-$D$3*B18 -> -1.8402951e-05 | G18: =Messdaten!J16 -> 1.925 | H18: =G18+$H$3 -> -2.605 | I18: =(J18-J$7)/J$7 -> 5.9663803e-07 | J18: =Messdaten!I16 -> 7357.8994
... A192: =Messdaten!B191 -> 3.72 | B192: =Messdaten!C191 -> -0.17288 | C192: =Messdaten!D191 -> -1.184 | D192: =INDIRECT(ADDRESS(ROW($H$6)+MATCH($A192,$H$7:$H$193,1),COLUMN($H192)+1))+(INDIRECT(ADDRESS(ROW($H$6)+MATCH($A192,$H$7:$H$193,1)+1,COLUMN($H192)+1))-INDIRECT(ADDRESS(ROW($H$6)+MATCH($A192,$H$7:$H$193,1),COLUMN($H192)+1)))*($A192-INDIRECT(ADDRESS(ROW($H$6)+MATCH($A192,$H$7:$H$193,1),COLUMN($H192))))/(INDIRECT(ADDRESS(ROW($H$6)+MATCH($A192,$H$7:$H$193,1)+1,COLUMN($H192)))-INDIRECT(ADDRESS(ROW($H$6)+MATCH($A192,$H$7:$H$193,1),COLUMN($H192)))) -> -0.0022438597 | E192: =D192-$D$2-$D$3*B192 -> 1.9135401e-05 | G192: =Messdaten!J190 -> 31.807 | H192: =G192+$H$3 -> 27.277 | I192: =(J192-J$7)/J$7 -> 4.9103718e-06 | J192: =Messdaten!I190 -> 7357.9312
A193: =Messdaten!B192 -> 3.74 | B193: =Messdaten!C192 -> -0.17384 | C193: =Messdaten!D192 -> -1.195 | D193: =INDIRECT(ADDRESS(ROW($H$6)+MATCH($A193,$H$7:$H$193,1),COLUMN($H193)+1))+(INDIRECT(ADDRESS(ROW($H$6)+MATCH($A193,$H$7:$H$193,1)+1,COLUMN($H193)+1))-INDIRECT(ADDRESS(ROW($H$6)+MATCH($A193,$H$7:$H$193,1),COLUMN($H193)+1)))*($A193-INDIRECT(ADDRESS(ROW($H$6)+MATCH($A193,$H$7:$H$193,1),COLUMN($H193))))/(INDIRECT(ADDRESS(ROW($H$6)+MATCH($A193,$H$7:$H$193,1)+1,COLUMN($H193)))-INDIRECT(ADDRESS(ROW($H$6)+MATCH($A193,$H$7:$H$193,1),COLUMN($H193)))) -> -0.0022572631 | E193: =D193-$D$2-$D$3*B193 -> 1.8360417e-05
A194: =Messdaten!B193 -> 3.76 | B194: =Messdaten!C193 -> -0.17485 | C194: =Messdaten!D193 -> -1.2 | D194: =INDIRECT(ADDRESS(ROW($H$6)+MATCH($A194,$H$7:$H$193,1),COLUMN($H194)+1))+(INDIRECT(ADDRESS(ROW($H$6)+MATCH($A194,$H$7:$H$193,1)+1,COLUMN($H194)+1))-INDIRECT(ADDRESS(ROW($H$6)+MATCH($A194,$H$7:$H$193,1),COLUMN($H194)+1)))*($A194-INDIRECT(ADDRESS(ROW($H$6)+MATCH($A194,$H$7:$H$193,1),COLUMN($H194))))/(INDIRECT(ADDRESS(ROW($H$6)+MATCH($A194,$H$7:$H$193,1)+1,COLUMN($H194)))-INDIRECT(ADDRESS(ROW($H$6)+MATCH($A194,$H$7:$H$193,1),COLUMN($H194)))) -> -0.0022706665 | E194: =D194-$D$2-$D$3*B194 -> 1.8243165e-05
A195: =Messdaten!B194 -> 3.78 | B195: =Messdaten!C194 -> -0.17589 | C195: =Messdaten!D194 -> -1.212 | D195: =INDIRECT(ADDRESS(ROW($H$6)+MATCH($A195,$H$7:$H$193,1),COLUMN($H195)+1))+(INDIRECT(ADDRESS(ROW($H$6)+MATCH($A195,$H$7:$H$193,1)+1,COLUMN($H195)+1))-INDIRECT(ADDRESS(ROW($H$6)+MATCH($A195,$H$7:$H$193,1),COLUMN($H195)+1)))*($A195-INDIRECT(ADDRESS(ROW($H$6)+MATCH($A195,$H$7:$H$193,1),COLUMN($H195))))/(INDIRECT(ADDRESS(ROW($H$6)+MATCH($A195,$H$7:$H$193,1)+1,COLUMN($H195)))-INDIRECT(ADDRESS(ROW($H$6)+MATCH($A195,$H$7:$H$193,1),COLUMN($H195)))) -> -0.0022839465 | E195: =D195-$D$2-$D$3*B195 -> 1.8643943e-05
A196: =Messdaten!B195 -> 3.8 | B196: =Messdaten!C195 -> -0.17689 | C196: =Messdaten!D195 -> -1.212 | D196: =INDIRECT(ADDRESS(ROW($H$6)+MATCH($A196,$H$7:$H$193,1),COLUMN($H196)+1))+(INDIRECT(ADDRESS(ROW($H$6)+MATCH($A196,$H$7:$H$193,1)+1,COLUMN($H196)+1))-INDIRECT(ADDRESS(ROW($H$6)+MATCH($A196,$H$7:$H$193,1),COLUMN($H196)+1)))*($A196-INDIRECT(ADDRESS(ROW($H$6)+MATCH($A196,$H$7:$H$193,1),COLUMN($H196))))/(INDIRECT(ADDRESS(ROW($H$6)+MATCH($A196,$H$7:$H$193,1)+1,COLUMN($H196)))-INDIRECT(ADDRESS(ROW($H$6)+MATCH($A196,$H$7:$H$193,1),COLUMN($H196)))) -> -0.0022971957 | E196: =D196-$D$2-$D$3*B196 -> 1.8549385e-05
A197: =Messdaten!B196 -> 3.82 | B197: =Messdaten!C196 -> -0.17789 | C197: =Messdaten!D196 -> -1.228 | D197: =INDIRECT(ADDRESS(ROW($H$6)+MATCH($A197,$H$7:$H$193,1),COLUMN($H197)+1))+(INDIRECT(ADDRESS(ROW($H$6)+MATCH($A197,$H$7:$H$193,1)+1,COLUMN($H197)+1))-INDIRECT(ADDRESS(ROW($H$6)+MATCH($A197,$H$7:$H$193,1),COLUMN($H197)+1)))*($A197-INDIRECT(ADDRESS(ROW($H$6)+MATCH($A197,$H$7:$H$193,1),COLUMN($H197))))/(INDIRECT(ADDRESS(ROW($H$6)+MATCH($A197,$H$7:$H$193,1)+1,COLUMN($H197)))-INDIRECT(ADDRESS(ROW($H$6)+MATCH($A197,$H$7:$H$193,1),COLUMN($H197)))) -> -0.0023104449 | E197: =D197-$D$2-$D$3*B197 -> 1.8454827e-05
A198: =Messdaten!B197 -> 3.84 | B198: =Messdaten!C197 -> -0.17886 | C198: =Messdaten!D197 -> -1.234 | D198: =INDIRECT(ADDRESS(ROW($H$6)+MATCH($A198,$H$7:$H$193,1),COLUMN($H198)+1))+(INDIRECT(ADDRESS(ROW($H$6)+MATCH($A198,$H$7:$H$193,1)+1,COLUMN($H198)+1))-INDIRECT(ADDRESS(ROW($H$6)+MATCH($A198,$H$7:$H$193,1),COLUMN($H198)+1)))*($A198-INDIRECT(ADDRESS(ROW($H$6)+MATCH($A198,$H$7:$H$193,1),COLUMN($H198))))/(INDIRECT(ADDRESS(ROW($H$6)+MATCH($A198,$H$7:$H$193,1)+1,COLUMN($H198)))-INDIRECT(ADDRESS(ROW($H$6)+MATCH($A198,$H$7:$H$193,1),COLUMN($H198)))) -> -0.0023236941 | E198: =D198-$D$2-$D$3*B198 -> 1.796563e-05
A199: =Messdaten!B198 -> 3.86 | B199: =Messdaten!C198 -> -0.1799 | C199: =Messdaten!D198 -> -1.234 | D199: =INDIRECT(ADDRESS(ROW($H$6)+MATCH($A199,$H$7:$H$193,1),COLUMN($H199)+1))+(INDIRECT(ADDRESS(ROW($H$6)+MATCH($A199,$H$7:$H$193,1)+1,COLUMN($H199)+1))-INDIRECT(ADDRESS(ROW($H$6)+MATCH($A199,$H$7:$H$193,1),COLUMN($H199)+1)))*($A199-INDIRECT(ADDRESS(ROW($H$6)+MATCH($A199,$H$7:$H$193,1),COLUMN($H199))))/(INDIRECT(ADDRESS(ROW($H$6)+MATCH($A199,$H$7:$H$193,1)+1,COLUMN($H199)))-INDIRECT(ADDRESS(ROW($H$6)+MATCH($A199,$H$7:$H$193,1),COLUMN($H199)))) -> -0.0023369432 | E199: =D199-$D$2-$D$3*B199 -> 1.8397256e-05
A200: =Messdaten!B199 -> 3.88 | B200: =Messdaten!C199 -> -0.18086 | C200: =Messdaten!D199 -> -1.251 | D200: =INDIRECT(ADDRESS(ROW($H$6)+MATCH($A200,$H$7:$H$193,1),COLUMN($H200)+1))+(INDIRECT(ADDRESS(ROW($H$6)+MATCH($A200,$H$7:$H$193,1)+1,COLUMN($H200)+1))-INDIRECT(ADDRESS(ROW($H$6)+MATCH($A200,$H$7:$H$193,1),COLUMN($H200)+1)))*($A200-INDIRECT(ADDRESS(ROW($H$6)+MATCH($A200,$H$7:$H$193,1),COLUMN($H200))))/(INDIRECT(ADDRESS(ROW($H$6)+MATCH($A200,$H$7:$H$193,1)+1,COLUMN($H200)))-INDIRECT(ADDRESS(ROW($H$6)+MATCH($A200,$H$7:$H$193,1),COLUMN($H200)))) -> -0.0023501924 | E200: =D200-$D$2-$D$3*B200 -> 1.7776513e-05
A201: =Messdaten!B200 -> 3.9 | B201: =Messdaten!C200 -> -0.18183 | C201: =Messdaten!D200 -> -1.234 | D201: =INDIRECT(ADDRESS(ROW($H$6)+MATCH($A201,$H$7:$H$193,1),COLUMN($H201)+1))+(INDIRECT(ADDRESS(ROW($H$6)+MATCH($A201,$H$7:$H$193,1)+1,COLUMN($H201)+1))-INDIRECT(ADDRESS(ROW($H$6)+MATCH($A201,$H$7:$H$193,1),COLUMN($H201)+1)))*($A201-INDIRECT(ADDRESS(ROW($H$6)+MATCH($A201,$H$7:$H$193,1),COLUMN($H201))))/(INDIRECT(ADDRESS(ROW($H$6)+MATCH($A201,$H$7:$H$193,1)+1,COLUMN($H201)))-INDIRECT(ADDRESS(ROW($H$6)+MATCH($A201,$H$7:$H$193,1),COLUMN($H201)))) -> -0.0023634416 | E201: =D201-$D$2-$D$3*B201 -> 1.7287316e-05
A202: =Messdaten!B201 -> 3.92 | B202: =Messdaten!C201 -> -0.18283 | C202: =Messdaten!D201 -> -1.268 | D202: =INDIRECT(ADDRESS(ROW($H$6)+MATCH($A202,$H$7:$H$193,1),COLUMN($H202)+1))+(INDIRECT(ADDRESS(ROW($H$6)+MATCH($A202,$H$7:$H$193,1)+1,COLUMN($H202)+1))-INDIRECT(ADDRESS(ROW($H$6)+MATCH($A202,$H$7:$H$193,1),COLUMN($H202)+1)))*($A202-INDIRECT(ADDRESS(ROW($H$6)+MATCH($A202,$H$7:$H$193,1),COLUMN($H202))))/(INDIRECT(ADDRESS(ROW($H$6)+MATCH($A202,$H$7:$H$193,1)+1,COLUMN($H202)))-INDIRECT(ADDRESS(ROW($H$6)+MATCH($A202,$H$7:$H$193,1),COLUMN($H202)))) -> -0.0023766908 | E202: =D202-$D$2-$D$3*B202 -> 1.7192758e-05
A203: =Messdaten!B202 -> 3.94 | B203: =Messdaten!C202 -> -0.18383 | C203: =Messdaten!D202 -> -1.262 | D203: =INDIRECT(ADDRESS(ROW($H$6)+MATCH($A203,$H$7:$H$193,1),COLUMN($H203)+1))+(INDIRECT(ADDRESS(ROW($H$6)+MATCH($A203,$H$7:$H$193,1)+1,COLUMN($H203)+1))-INDIRECT(ADDRESS(ROW($H$6)+MATCH($A203,$H$7:$H$193,1),COLUMN($H203)+1)))*($A203-INDIRECT(ADDRESS(ROW($H$6)+MATCH($A203,$H$7:$H$193,1),COLUMN($H203))))/(INDIRECT(ADDRESS(ROW($H$6)+MATCH($A203,$H$7:$H$193,1)+1,COLUMN($H203)))-INDIRECT(ADDRESS(ROW($H$6)+MATCH($A203,$H$7:$H$193,1),COLUMN($H203)))) -> -0.0023900029 | E203: =D203-$D$2-$D$3*B203 -> 1.7035271e-05
A204: =Messdaten!B203 -> 3.96 | B204: =Messdaten!C203 -> -0.18468 | C204: =Messdaten!D203 -> -1.268 | D204: =INDIRECT(ADDRESS(ROW($H$6)+MATCH($A204,$H$7:$H$193,1),COLUMN($H204)+1))+(INDIRECT(ADDRESS(ROW($H$6)+MATCH($A204,$H$7:$H$193,1)+1,COLUMN($H204)+1))-INDIRECT(ADDRESS(ROW($H$6)+MATCH($A204,$H$7:$H$193,1),COLUMN($H204)+1)))*($A204-INDIRECT(ADDRESS(ROW($H$6)+MATCH($A204,$H$7:$H$193,1),COLUMN($H204))))/(INDIRECT(ADDRESS(ROW($H$6)+MATCH($A204,$H$7:$H$193,1)+1,COLUMN($H204)))-INDIRECT(ADDRESS(ROW($H$6)+MATCH($A204,$H$7:$H$193,1),COLUMN($H204)))) -> -0.0024035667 | E204: =D204-$D$2-$D$3*B204 -> 1.4652877e-05
... A1381: =Messdaten!B1380 -> 27.5 | B1381: =Messdaten!C1380 -> 0 | C1381: =Messdaten!D1380 -> 0.005 | D1381: =INDIRECT(ADDRESS(ROW($H$6)+MATCH($A1381,$H$7:$H$193,1),COLUMN($H1381)+1))+(INDIRECT(ADDRESS(ROW($H$6)+MATCH($A1381,$H$7:$H$193,1)+1,COLUMN($H1381)+1))-INDIRECT(ADDRESS(ROW($H$6)+MATCH($A1381,$H$7:$H$193,1),COLUMN($H1381)+1)))*($A1381-INDIRECT(ADDRESS(ROW($H$6)+MATCH($A1381,$H$7:$H$193,1),COLUMN($H1381))))/(INDIRECT(ADDRESS(ROW($H$6)+MATCH($A1381,$H$7:$H$193,1)+1,COLUMN($H1381)))-INDIRECT(ADDRESS(ROW($H$6)+MATCH($A1381,$H$7:$H$193,1),COLUMN($H1381)))) -> 4.950516e-06 | E1381: =D1381-$D$2-$D$3*B1381 -> -6.2247139e-06

Sheet R13
A2: Durchbiegung | C2: a0 = | D2: =INTERCEPT(D7:D1381,B7:B1381) -> 8.6845496e-06 | G2: Widerstand 101
C3: a1 = | D3: =SLOPE(D7:D1381,B7:B1381) -> 0.0083138158 | H3: -4.53
A5: Zeit | B5: Pos | C5: Kraft | D5: DR / R | E5: DR / R mionus Gerade | G5: Zeit | H5: Zeit (korr) | I5: DR / R | J5: Widerstand
A6: [s] | B6: [mm] | C6: [N] | G6: [s] | H6: [s] | J6: [W]
A7: =Messdaten!B6 -> 0.02 | B7: =Messdaten!C6 -> 0 | C7: =Messdaten!D6 -> 0.011 | D7: =INDIRECT(ADDRESS(ROW($H$6)+MATCH($A7,$H$7:$H$193,1),COLUMN($H7)+1))+(INDIRECT(ADDRESS(ROW($H$6)+MATCH($A7,$H$7:$H$193,1)+1,COLUMN($H7)+1))-INDIRECT(ADDRESS(ROW($H$6)+MATCH($A7,$H$7:$H$193,1),COLUMN($H7)+1)))*($A7-INDIRECT(ADDRESS(ROW($H$6)+MATCH($A7,$H$7:$H$193,1),COLUMN($H7))))/(INDIRECT(ADDRESS(ROW($H$6)+MATCH($A7,$H$7:$H$193,1)+1,COLUMN($H7)))-INDIRECT(ADDRESS(ROW($H$6)+MATCH($A7,$H$7:$H$193,1),COLUMN($H7)))) -> -6.1512195e-07 | E7: =D7-$D$2-$D$3*B7 -> -9.2996716e-06 | G7: =Messdaten!M5 -> 0.075 | H7: =G7+$H$3 -> -4.455 | I7: =(J7-J$7)/J$7 -> 0 | J7: =Messdaten!L5 -> 7116.3106
A8: =Messdaten!B7 -> 0.04 | B8: =Messdaten!C7 -> 0 | C8: =Messdaten!D7 -> 0.011 | D8: =INDIRECT(ADDRESS(ROW($H$6)+MATCH($A8,$H$7:$H$193,1),COLUMN($H8)+1))+(INDIRECT(ADDRESS(ROW($H$6)+MATCH($A8,$H$7:$H$193,1)+1,COLUMN($H8)+1))-INDIRECT(ADDRESS(ROW($H$6)+MATCH($A8,$H$7:$H$193,1),COLUMN($H8)+1)))*($A8-INDIRECT(ADDRESS(ROW($H$6)+MATCH($A8,$H$7:$H$193,1),COLUMN($H8))))/(INDIRECT(ADDRESS(ROW($H$6)+MATCH($A8,$H$7:$H$193,1)+1,COLUMN($H8)))-INDIRECT(ADDRESS(ROW($H$6)+MATCH($A8,$H$7:$H$193,1),COLUMN($H8)))) -> -5.1212192e-07 | E8: =D8-$D$2-$D$3*B8 -> -9.1966716e-06 | G8: =Messdaten!M6 -> 0.247 | H8: =G8+$H$3 -> -4.283 | I8: =(J8-J$7)/J$7 -> 5.4803679e-07 | J8: =Messdaten!L6 -> 7116.3144
A9: =Messdaten!B8 -> 0.06 | B9: =Messdaten!C8 -> 0 | C9: =Messdaten!D8 -> 0.017 | D9: =INDIRECT(ADDRESS(ROW($H$6)+MATCH($A9,$H$7:$H$193,1),COLUMN($H9)+1))+(INDIRECT(ADDRESS(ROW($H$6)+MATCH($A9,$H$7:$H$193,1)+1,COLUMN($H9)+1))-INDIRECT(ADDRESS(ROW($H$6)+MATCH($A9,$H$7:$H$193,1),COLUMN($H9)+1)))*($A9-INDIRECT(ADDRESS(ROW($H$6)+MATCH($A9,$H$7:$H$193,1),COLUMN($H9))))/(INDIRECT(ADDRESS(ROW($H$6)+MATCH($A9,$H$7:$H$193,1)+1,COLUMN($H9)))-INDIRECT(ADDRESS(ROW($H$6)+MATCH($A9,$H$7:$H$193,1),COLUMN($H9)))) -> -4.0035771e-07 | E9: =D9-$D$2-$D$3*B9 -> -9.0849073e-06 | G9: =Messdaten!M7 -> 0.419 | H9: =G9+$H$3 -> -4.111 | I9: =(J9-J$7)/J$7 -> 0 | J9: =Messdaten!L7 -> 7116.3106
A10: =Messdaten!B9 -> 0.08 | B10: =Messdaten!C9 -> 0 | C10: =Messdaten!D9 -> 0.011 | D10: =INDIRECT(ADDRESS(ROW($H$6)+MATCH($A10,$H$7:$H$193,1),COLUMN($H10)+1))+(INDIRECT(ADDRESS(ROW($H$6)+MATCH($A10,$H$7:$H$193,1)+1,COLUMN($H10)+1))-INDIRECT(ADDRESS(ROW($H$6)+MATCH($A10,$H$7:$H$193,1),COLUMN($H10)+1)))*($A10-INDIRECT(ADDRESS(ROW($H$6)+MATCH($A10,$H$7:$H$193,1),COLUMN($H10))))/(INDIRECT(ADDRESS(ROW($H$6)+MATCH($A10,$H$7:$H$193,1)+1,COLUMN($H10)))-INDIRECT(ADDRESS(ROW($H$6)+MATCH($A10,$H$7:$H$193,1),COLUMN($H10)))) -> -2.8859349e-07 | E10: =D10-$D$2-$D$3*B10 -> -8.9731431e-06 | G10: =Messdaten!M8 -> 0.591 | H10: =G10+$H$3 -> -3.939 | I10: =(J10-J$7)/J$7 -> 3.428743e-07 | J10: =Messdaten!L8 -> 7116.313
A11: =Messdaten!B10 -> 0.1 | B11: =Messdaten!C10 -> 0 | C11: =Messdaten!D10 -> 0.022 | D11: =INDIRECT(ADDRESS(ROW($H$6)+MATCH($A11,$H$7:$H$193,1),COLUMN($H11)+1))+(INDIRECT(ADDRESS(ROW($H$6)+MATCH($A11,$H$7:$H$193,1)+1,COLUMN($H11)+1))-INDIRECT(ADDRESS(ROW($H$6)+MATCH($A11,$H$7:$H$193,1),COLUMN($H11)+1)))*($A11-INDIRECT(ADDRESS(ROW($H$6)+MATCH($A11,$H$7:$H$193,1),COLUMN($H11))))/(INDIRECT(ADDRESS(ROW($H$6)+MATCH($A11,$H$7:$H$193,1)+1,COLUMN($H11)))-INDIRECT(ADDRESS(ROW($H$6)+MATCH($A11,$H$7:$H$193,1),COLUMN($H11)))) -> -1.7682928e-07 | E11: =D11-$D$2-$D$3*B11 -> -8.8613789e-06 | G11: =Messdaten!M9 -> 0.763 | H11: =G11+$H$3 -> -3.767 | I11: =(J11-J$7)/J$7 -> -2.0656771e-07 | J11: =Messdaten!L9 -> 7116.3091
A12: =Messdaten!B11 -> 0.12 | B12: =Messdaten!C11 -> 0 | C12: =Messdaten!D11 -> 0.017 | D12: =INDIRECT(ADDRESS(ROW($H$6)+MATCH($A12,$H$7:$H$193,1),COLUMN($H12)+1))+(INDIRECT(ADDRESS(ROW($H$6)+MATCH($A12,$H$7:$H$193,1)+1,COLUMN($H12)+1))-INDIRECT(ADDRESS(ROW($H$6)+MATCH($A12,$H$7:$H$193,1),COLUMN($H12)+1)))*($A12-INDIRECT(ADDRESS(ROW($H$6)+MATCH($A12,$H$7:$H$193,1),COLUMN($H12))))/(INDIRECT(ADDRESS(ROW($H$6)+MATCH($A12,$H$7:$H$193,1)+1,COLUMN($H12)))-INDIRECT(ADDRESS(ROW($H$6)+MATCH($A12,$H$7:$H$193,1),COLUMN($H12)))) -> -6.5065072e-08 | E12: =D12-$D$2-$D$3*B12 -> -8.7496147e-06 | G12: =Messdaten!M10 -> 0.936 | H12: =G12+$H$3 -> -3.594 | I12: =(J12-J$7)/J$7 -> 1.509209e-06 | J12: =Messdaten!L10 -> 7116.3213
A13: =Messdaten!B12 -> 0.14 | B13: =Messdaten!C12 -> 0 | C13: =Messdaten!D12 -> 0.011 | D13: =INDIRECT(ADDRESS(ROW($H$6)+MATCH($A13,$H$7:$H$193,1),COLUMN($H13)+1))+(INDIRECT(ADDRESS(ROW($H$6)+MATCH($A13,$H$7:$H$193,1)+1,COLUMN($H13)+1))-INDIRECT(ADDRESS(ROW($H$6)+MATCH($A13,$H$7:$H$193,1),COLUMN($H13)+1)))*($A13-INDIRECT(ADDRESS(ROW($H$6)+MATCH($A13,$H$7:$H$193,1),COLUMN($H13))))/(INDIRECT(ADDRESS(ROW($H$6)+MATCH($A13,$H$7:$H$193,1)+1,COLUMN($H13)))-INDIRECT(ADDRESS(ROW($H$6)+MATCH($A13,$H$7:$H$193,1),COLUMN($H13)))) -> 4.669914e-08 | E13: =D13-$D$2-$D$3*B13 -> -8.6378505e-06 | G13: =Messdaten!M11 -> 1.108 | H13: =G13+$H$3 -> -3.422 | I13: =(J13-J$7)/J$7 -> -4.117302e-07 | J13: =Messdaten!L11 -> 7116.3076
A14: =Messdaten!B13 -> 0.16 | B14: =Messdaten!C13 -> 0 | C14: =Messdaten!D13 -> 0.011 | D14: =INDIRECT(ADDRESS(ROW($H$6)+MATCH($A14,$H$7:$H$193,1),COLUMN($H14)+1))+(INDIRECT(ADDRESS(ROW($H$6)+MATCH($A14,$H$7:$H$193,1)+1,COLUMN($H14)+1))-INDIRECT(ADDRESS(ROW($H$6)+MATCH($A14,$H$7:$H$193,1),COLUMN($H14)+1)))*($A14-INDIRECT(ADDRESS(ROW($H$6)+MATCH($A14,$H$7:$H$193,1),COLUMN($H14))))/(INDIRECT(ADDRESS(ROW($H$6)+MATCH($A14,$H$7:$H$193,1)+1,COLUMN($H14)))-INDIRECT(ADDRESS(ROW($H$6)+MATCH($A14,$H$7:$H$193,1),COLUMN($H14)))) -> 1.5846335e-07 | E14: =D14-$D$2-$D$3*B14 -> -8.5260863e-06 | G14: =Messdaten!M12 -> 1.28 | H14: =G14+$H$3 -> -3.25 | I14: =(J14-J$7)/J$7 -> 1.8520833e-06 | J14: =Messdaten!L12 -> 7116.3237
A15: =Messdaten!B14 -> 0.18 | B15: =Messdaten!C14 -> 0 | C15: =Messdaten!D14 -> 0.011 | D15: =INDIRECT(ADDRESS(ROW($H$6)+MATCH($A15,$H$7:$H$193,1),COLUMN($H15)+1))+(INDIRECT(ADDRESS(ROW($H$6)+MATCH($A15,$H$7:$H$193,1)+1,COLUMN($H15)+1))-INDIRECT(ADDRESS(ROW($H$6)+MATCH($A15,$H$7:$H$193,1),COLUMN($H15)+1)))*($A15-INDIRECT(ADDRESS(ROW($H$6)+MATCH($A15,$H$7:$H$193,1),COLUMN($H15))))/(INDIRECT(ADDRESS(ROW($H$6)+MATCH($A15,$H$7:$H$193,1)+1,COLUMN($H15)))-INDIRECT(ADDRESS(ROW($H$6)+MATCH($A15,$H$7:$H$193,1),COLUMN($H15)))) -> 2.7022756e-07 | E15: =D15-$D$2-$D$3*B15 -> -8.4143221e-06 | G15: =Messdaten!M13 -> 1.452 | H15: =G15+$H$3 -> -3.078 | I15: =(J15-J$7)/J$7 -> -2.0656771e-07 | J15: =Messdaten!L13 -> 7116.3091
A16: =Messdaten!B15 -> 0.2 | B16: =Messdaten!C15 -> 0 | C16: =Messdaten!D15 -> 0.017 | D16: =INDIRECT(ADDRESS(ROW($H$6)+MATCH($A16,$H$7:$H$193,1),COLUMN($H16)+1))+(INDIRECT(ADDRESS(ROW($H$6)+MATCH($A16,$H$7:$H$193,1)+1,COLUMN($H16)+1))-INDIRECT(ADDRESS(ROW($H$6)+MATCH($A16,$H$7:$H$193,1),COLUMN($H16)+1)))*($A16-INDIRECT(ADDRESS(ROW($H$6)+MATCH($A16,$H$7:$H$193,1),COLUMN($H16))))/(INDIRECT(ADDRESS(ROW($H$6)+MATCH($A16,$H$7:$H$193,1)+1,COLUMN($H16)))-INDIRECT(ADDRESS(ROW($H$6)+MATCH($A16,$H$7:$H$193,1),COLUMN($H16)))) -> -7.5458817e-07 | E16: =D16-$D$2-$D$3*B16 -> -9.4391378e-06 | G16: =Messdaten!M14 -> 1.624 | H16: =G16+$H$3 -> -2.906 | I16: =(J16-J$7)/J$7 -> -2.0656771e-07 | J16: =Messdaten!L14 -> 7116.3091
A17: =Messdaten!B16 -> 0.22 | B17: =Messdaten!C16 -> 0 | C17: =Messdaten!D16 -> 0 | D17: =INDIRECT(ADDRESS(ROW($H$6)+MATCH($A17,$H$7:$H$193,1),COLUMN($H17)+1))+(INDIRECT(ADDRESS(ROW($H$6)+MATCH($A17,$H$7:$H$193,1)+1,COLUMN($H17)+1))-INDIRECT(ADDRESS(ROW($H$6)+MATCH($A17,$H$7:$H$193,1),COLUMN($H17)+1)))*($A17-INDIRECT(ADDRESS(ROW($H$6)+MATCH($A17,$H$7:$H$193,1),COLUMN($H17))))/(INDIRECT(ADDRESS(ROW($H$6)+MATCH($A17,$H$7:$H$193,1)+1,COLUMN($H17)))-INDIRECT(ADDRESS(ROW($H$6)+MATCH($A17,$H$7:$H$193,1),COLUMN($H17)))) -> -3.8901952e-06 | E17: =D17-$D$2-$D$3*B17 -> -1.2574745e-05 | G17: =Messdaten!M15 -> 1.796 | H17: =G17+$H$3 -> -2.734 | I17: =(J17-J$7)/J$7 -> 3.428743e-07 | J17: =Messdaten!L15 -> 7116.313
A18: =Messdaten!B17 -> 0.24 | B18: =Messdaten!C17 -> 0 | C18: =Messdaten!D17 -> 0.011 | D18: =INDIRECT(ADDRESS(ROW($H$6)+MATCH($A18,$H$7:$H$193,1),COLUMN($H18)+1))+(INDIRECT(ADDRESS(ROW($H$6)+MATCH($A18,$H$7:$H$193,1)+1,COLUMN($H18)+1))-INDIRECT(ADDRESS(ROW($H$6)+MATCH($A18,$H$7:$H$193,1),COLUMN($H18)+1)))*($A18-INDIRECT(ADDRESS(ROW($H$6)+MATCH($A18,$H$7:$H$193,1),COLUMN($H18))))/(INDIRECT(ADDRESS(ROW($H$6)+MATCH($A18,$H$7:$H$193,1)+1,COLUMN($H18)))-INDIRECT(ADDRESS(ROW($H$6)+MATCH($A18,$H$7:$H$193,1),COLUMN($H18)))) -> -7.0258023e-06 | E18: =D18-$D$2-$D$3*B18 -> -1.5710352e-05 | G18: =Messdaten!M16 -> 1.968 | H18: =G18+$H$3 -> -2.562 | I18: =(J18-J$7)/J$7 -> -4.8058611e-07 | J18: =Messdaten!L16 -> 7116.3071
... A189: =Messdaten!B188 -> 3.66 | B189: =Messdaten!C188 -> -0.16983 | C189: =Messdaten!D188 -> -1.161 | D189: =INDIRECT(ADDRESS(ROW($H$6)+MATCH($A189,$H$7:$H$193,1),COLUMN($H189)+1))+(INDIRECT(ADDRESS(ROW($H$6)+MATCH($A189,$H$7:$H$193,1)+1,COLUMN($H189)+1))-INDIRECT(ADDRESS(ROW($H$6)+MATCH($A189,$H$7:$H$193,1),COLUMN($H189)+1)))*($A189-INDIRECT(ADDRESS(ROW($H$6)+MATCH($A189,$H$7:$H$193,1),COLUMN($H189))))/(INDIRECT(ADDRESS(ROW($H$6)+MATCH($A189,$H$7:$H$193,1)+1,COLUMN($H189)))-INDIRECT(ADDRESS(ROW($H$6)+MATCH($A189,$H$7:$H$193,1),COLUMN($H189)))) -> -0.0013916791 | E189: =D189-$D$2-$D$3*B189 -> 1.1571725e-05 | G189: =Messdaten!M187 -> 31.336 | H189: =G189+$H$3 -> 26.806 | I189: =(J189-J$7)/J$7 -> 1.8520833e-06 | J189: =Messdaten!L187 -> 7116.3237
A190: =Messdaten!B189 -> 3.68 | B190: =Messdaten!C189 -> -0.17083 | C190: =Messdaten!D189 -> -1.178 | D190: =INDIRECT(ADDRESS(ROW($H$6)+MATCH($A190,$H$7:$H$193,1),COLUMN($H190)+1))+(INDIRECT(ADDRESS(ROW($H$6)+MATCH($A190,$H$7:$H$193,1)+1,COLUMN($H190)+1))-INDIRECT(ADDRESS(ROW($H$6)+MATCH($A190,$H$7:$H$193,1),COLUMN($H190)+1)))*($A190-INDIRECT(ADDRESS(ROW($H$6)+MATCH($A190,$H$7:$H$193,1),COLUMN($H190))))/(INDIRECT(ADDRESS(ROW($H$6)+MATCH($A190,$H$7:$H$193,1)+1,COLUMN($H190)))-INDIRECT(ADDRESS(ROW($H$6)+MATCH($A190,$H$7:$H$193,1),COLUMN($H190)))) -> -0.0014000565 | E190: =D190-$D$2-$D$3*B190 -> 1.1508127e-05
A191: =Messdaten!B190 -> 3.7 | B191: =Messdaten!C190 -> -0.17184 | C191: =Messdaten!D190 -> -1.184 | D191: =INDIRECT(ADDRESS(ROW($H$6)+MATCH($A191,$H$7:$H$193,1),COLUMN($H191)+1))+(INDIRECT(ADDRESS(ROW($H$6)+MATCH($A191,$H$7:$H$193,1)+1,COLUMN($H191)+1))-INDIRECT(ADDRESS(ROW($H$6)+MATCH($A191,$H$7:$H$193,1),COLUMN($H191)+1)))*($A191-INDIRECT(ADDRESS(ROW($H$6)+MATCH($A191,$H$7:$H$193,1),COLUMN($H191))))/(INDIRECT(ADDRESS(ROW($H$6)+MATCH($A191,$H$7:$H$193,1)+1,COLUMN($H191)))-INDIRECT(ADDRESS(ROW($H$6)+MATCH($A191,$H$7:$H$193,1),COLUMN($H191)))) -> -0.0014084339 | E191: =D191-$D$2-$D$3*B191 -> 1.1527667e-05
A192: =Messdaten!B191 -> 3.72 | B192: =Messdaten!C191 -> -0.17288 | C192: =Messdaten!D191 -> -1.184 | D192: =INDIRECT(ADDRESS(ROW($H$6)+MATCH($A192,$H$7:$H$193,1),COLUMN($H192)+1))+(INDIRECT(ADDRESS(ROW($H$6)+MATCH($A192,$H$7:$H$193,1)+1,COLUMN($H192)+1))-INDIRECT(ADDRESS(ROW($H$6)+MATCH($A192,$H$7:$H$193,1),COLUMN($H192)+1)))*($A192-INDIRECT(ADDRESS(ROW($H$6)+MATCH($A192,$H$7:$H$193,1),COLUMN($H192))))/(INDIRECT(ADDRESS(ROW($H$6)+MATCH($A192,$H$7:$H$193,1)+1,COLUMN($H192)))-INDIRECT(ADDRESS(ROW($H$6)+MATCH($A192,$H$7:$H$193,1),COLUMN($H192)))) -> -0.0014168113 | E192: =D192-$D$2-$D$3*B192 -> 1.1796622e-05
A193: =Messdaten!B192 -> 3.74 | B193: =Messdaten!C192 -> -0.17384 | C193: =Messdaten!D192 -> -1.195 | D193: =INDIRECT(ADDRESS(ROW($H$6)+MATCH($A193,$H$7:$H$193,1),COLUMN($H193)+1))+(INDIRECT(ADDRESS(ROW($H$6)+MATCH($A193,$H$7:$H$193,1)+1,COLUMN($H193)+1))-INDIRECT(ADDRESS(ROW($H$6)+MATCH($A193,$H$7:$H$193,1),COLUMN($H193)+1)))*($A193-INDIRECT(ADDRESS(ROW($H$6)+MATCH($A193,$H$7:$H$193,1),COLUMN($H193))))/(INDIRECT(ADDRESS(ROW($H$6)+MATCH($A193,$H$7:$H$193,1)+1,COLUMN($H193)))-INDIRECT(ADDRESS(ROW($H$6)+MATCH($A193,$H$7:$H$193,1),COLUMN($H193)))) -> -0.0014251887 | E193: =D193-$D$2-$D$3*B193 -> 1.1400471e-05
A194: =Messdaten!B193 -> 3.76 | B194: =Messdaten!C193 -> -0.17485 | C194: =Messdaten!D193 -> -1.2 | D194: =INDIRECT(ADDRESS(ROW($H$6)+MATCH($A194,$H$7:$H$193,1),COLUMN($H194)+1))+(INDIRECT(ADDRESS(ROW($H$6)+MATCH($A194,$H$7:$H$193,1)+1,COLUMN($H194)+1))-INDIRECT(ADDRESS(ROW($H$6)+MATCH($A194,$H$7:$H$193,1),COLUMN($H194)+1)))*($A194-INDIRECT(ADDRESS(ROW($H$6)+MATCH($A194,$H$7:$H$193,1),COLUMN($H194))))/(INDIRECT(ADDRESS(ROW($H$6)+MATCH($A194,$H$7:$H$193,1)+1,COLUMN($H194)))-INDIRECT(ADDRESS(ROW($H$6)+MATCH($A194,$H$7:$H$193,1),COLUMN($H194)))) -> -0.0014335661 | E194: =D194-$D$2-$D$3*B194 -> 1.1420011e-05
A195: =Messdaten!B194 -> 3.78 | B195: =Messdaten!C194 -> -0.17589 | C195: =Messdaten!D194 -> -1.212 | D195: =INDIRECT(ADDRESS(ROW($H$6)+MATCH($A195,$H$7:$H$193,1),COLUMN($H195)+1))+(INDIRECT(ADDRESS(ROW($H$6)+MATCH($A195,$H$7:$H$193,1)+1,COLUMN($H195)+1))-INDIRECT(ADDRESS(ROW($H$6)+MATCH($A195,$H$7:$H$193,1),COLUMN($H195)+1)))*($A195-INDIRECT(ADDRESS(ROW($H$6)+MATCH($A195,$H$7:$H$193,1),COLUMN($H195))))/(INDIRECT(ADDRESS(ROW($H$6)+MATCH($A195,$H$7:$H$193,1)+1,COLUMN($H195)))-INDIRECT(ADDRESS(ROW($H$6)+MATCH($A195,$H$7:$H$193,1),COLUMN($H195)))) -> -0.0014419435 | E195: =D195-$D$2-$D$3*B195 -> 1.1688966e-05
A196: =Messdaten!B195 -> 3.8 | B196: =Messdaten!C195 -> -0.17689 | C196: =Messdaten!D195 -> -1.212 | D196: =INDIRECT(ADDRESS(ROW($H$6)+MATCH($A196,$H$7:$H$193,1),COLUMN($H196)+1))+(INDIRECT(ADDRESS(ROW($H$6)+MATCH($A196,$H$7:$H$193,1)+1,COLUMN($H196)+1))-INDIRECT(ADDRESS(ROW($H$6)+MATCH($A196,$H$7:$H$193,1),COLUMN($H196)+1)))*($A196-INDIRECT(ADDRESS(ROW($H$6)+MATCH($A196,$H$7:$H$193,1),COLUMN($H196))))/(INDIRECT(ADDRESS(ROW($H$6)+MATCH($A196,$H$7:$H$193,1)+1,COLUMN($H196)))-INDIRECT(ADDRESS(ROW($H$6)+MATCH($A196,$H$7:$H$193,1),COLUMN($H196)))) -> -0.001450321 | E196: =D196-$D$2-$D$3*B196 -> 1.1625367e-05
A197: =Messdaten!B196 -> 3.82 | B197: =Messdaten!C196 -> -0.17789 | C197: =Messdaten!D196 -> -1.228 | D197: =INDIRECT(ADDRESS(ROW($H$6)+MATCH($A197,$H$7:$H$193,1),COLUMN($H197)+1))+(INDIRECT(ADDRESS(ROW($H$6)+MATCH($A197,$H$7:$H$193,1)+1,COLUMN($H197)+1))-INDIRECT(ADDRESS(ROW($H$6)+MATCH($A197,$H$7:$H$193,1),COLUMN($H197)+1)))*($A197-INDIRECT(ADDRESS(ROW($H$6)+MATCH($A197,$H$7:$H$193,1),COLUMN($H197))))/(INDIRECT(ADDRESS(ROW($H$6)+MATCH($A197,$H$7:$H$193,1)+1,COLUMN($H197)))-INDIRECT(ADDRESS(ROW($H$6)+MATCH($A197,$H$7:$H$193,1),COLUMN($H197)))) -> -0.0014586412 | E197: =D197-$D$2-$D$3*B197 -> 1.1618909e-05
A198: =Messdaten!B197 -> 3.84 | B198: =Messdaten!C197 -> -0.17886 | C198: =Messdaten!D197 -> -1.234 | D198: =INDIRECT(ADDRESS(ROW($H$6)+MATCH($A198,$H$7:$H$193,1),COLUMN($H198)+1))+(INDIRECT(ADDRESS(ROW($H$6)+MATCH($A198,$H$7:$H$193,1)+1,COLUMN($H198)+1))-INDIRECT(ADDRESS(ROW($H$6)+MATCH($A198,$H$7:$H$193,1),COLUMN($H198)+1)))*($A198-INDIRECT(ADDRESS(ROW($H$6)+MATCH($A198,$H$7:$H$193,1),COLUMN($H198))))/(INDIRECT(ADDRESS(ROW($H$6)+MATCH($A198,$H$7:$H$193,1)+1,COLUMN($H198)))-INDIRECT(ADDRESS(ROW($H$6)+MATCH($A198,$H$7:$H$193,1),COLUMN($H198)))) -> -0.0014669307 | E198: =D198-$D$2-$D$3*B198 -> 1.1393805e-05
A199: =Messdaten!B198 -> 3.86 | B199: =Messdaten!C198 -> -0.1799 | C199: =Messdaten!D198 -> -1.234 | D199: =INDIRECT(ADDRESS(ROW($H$6)+MATCH($A199,$H$7:$H$193,1),COLUMN($H199)+1))+(INDIRECT(ADDRESS(ROW($H$6)+MATCH($A199,$H$7:$H$193,1)+1,COLUMN($H199)+1))-INDIRECT(ADDRESS(ROW($H$6)+MATCH($A199,$H$7:$H$193,1),COLUMN($H199)+1)))*($A199-INDIRECT(ADDRESS(ROW($H$6)+MATCH($A199,$H$7:$H$193,1),COLUMN($H199))))/(INDIRECT(ADDRESS(ROW($H$6)+MATCH($A199,$H$7:$H$193,1)+1,COLUMN($H199)))-INDIRECT(ADDRESS(ROW($H$6)+MATCH($A199,$H$7:$H$193,1),COLUMN($H199)))) -> -0.0014752202 | E199: =D199-$D$2-$D$3*B199 -> 1.1750668e-05
A200: =Messdaten!B199 -> 3.88 | B200: =Messdaten!C199 -> -0.18086 | C200: =Messdaten!D199 -> -1.251 | D200: =INDIRECT(ADDRESS(ROW($H$6)+MATCH($A200,$H$7:$H$193,1),COLUMN($H200)+1))+(INDIRECT(ADDRESS(ROW($H$6)+MATCH($A200,$H$7:$H$193,1)+1,COLUMN($H200)+1))-INDIRECT(ADDRESS(ROW($H$6)+MATCH($A200,$H$7:$H$193,1),COLUMN($H200)+1)))*($A200-INDIRECT(ADDRESS(ROW($H$6)+MATCH($A200,$H$7:$H$193,1),COLUMN($H200))))/(INDIRECT(ADDRESS(ROW($H$6)+MATCH($A200,$H$7:$H$193,1)+1,COLUMN($H200)))-INDIRECT(ADDRESS(ROW($H$6)+MATCH($A200,$H$7:$H$193,1),COLUMN($H200)))) -> -0.0014835097 | E200: =D200-$D$2-$D$3*B200 -> 1.1442425e-05
A201: =Messdaten!B200 -> 3.9 | B201: =Messdaten!C200 -> -0.18183 | C201: =Messdaten!D200 -> -1.234 | D201: =INDIRECT(ADDRESS(ROW($H$6)+MATCH($A201,$H$7:$H$193,1),COLUMN($H201)+1))+(INDIRECT(ADDRESS(ROW($H$6)+MATCH($A201,$H$7:$H$193,1)+1,COLUMN($H201)+1))-INDIRECT(ADDRESS(ROW($H$6)+MATCH($A201,$H$7:$H$193,1),COLUMN($H201)+1)))*($A201-INDIRECT(ADDRESS(ROW($H$6)+MATCH($A201,$H$7:$H$193,1),COLUMN($H201))))/(INDIRECT(ADDRESS(ROW($H$6)+MATCH($A201,$H$7:$H$193,1)+1,COLUMN($H201)))-INDIRECT(ADDRESS(ROW($H$6)+MATCH($A201,$H$7:$H$193,1),COLUMN($H201)))) -> -0.0014917993 | E201: =D201-$D$2-$D$3*B201 -> 1.121732e-05
... A1381: =Messdaten!B1380 -> 27.5 | B1381: =Messdaten!C1380 -> 0 | C1381: =Messdaten!D1380 -> 0.005 | D1381: =INDIRECT(ADDRESS(ROW($H$6)+MATCH($A1381,$H$7:$H$193,1),COLUMN($H1381)+1))+(INDIRECT(ADDRESS(ROW($H$6)+MATCH($A1381,$H$7:$H$193,1)+1,COLUMN($H1381)+1))-INDIRECT(ADDRESS(ROW($H$6)+MATCH($A1381,$H$7:$H$193,1),COLUMN($H1381)+1)))*($A1381-INDIRECT(ADDRESS(ROW($H$6)+MATCH($A1381,$H$7:$H$193,1),COLUMN($H1381))))/(INDIRECT(ADDRESS(ROW($H$6)+MATCH($A1381,$H$7:$H$193,1)+1,COLUMN($H1381)))-INDIRECT(ADDRESS(ROW($H$6)+MATCH($A1381,$H$7:$H$193,1),COLUMN($H1381)))) -> 1.9000332e-06 | E1381: =D1381-$D$2-$D$3*B1381 -> -6.7845164e-06

Sheet R12
A2: Durchbiegung | C2: a0 = | D2: =INTERCEPT(D7:D1381,B7:B1381) -> 5.0410995e-06 | G2: Widerstand 101
C3: a1 = | D3: =SLOPE(D7:D1381,B7:B1381) -> 0.012725922 | H3: -4.53
A5: Zeit | B5: Pos | C5: Kraft | D5: DR / R | E5: DR / R mionus Gerade | G5: Zeit | H5: Zeit (korr) | I5: DR / R | J5: Widerstand
A6: [s] | B6: [mm] | C6: [N] | G6: [s] | H6: [s] | J6: [W]
A7: =Messdaten!B6 -> 0.02 | B7: =Messdaten!C6 -> 0 | C7: =Messdaten!D6 -> 0.011 | D7: =INDIRECT(ADDRESS(ROW($H$6)+MATCH($A7,$H$7:$H$193,1),COLUMN($H7)+1))+(INDIRECT(ADDRESS(ROW($H$6)+MATCH($A7,$H$7:$H$193,1)+1,COLUMN($H7)+1))-INDIRECT(ADDRESS(ROW($H$6)+MATCH($A7,$H$7:$H$193,1),COLUMN($H7)+1)))*($A7-INDIRECT(ADDRESS(ROW($H$6)+MATCH($A7,$H$7:$H$193,1),COLUMN($H7))))/(INDIRECT(ADDRESS(ROW($H$6)+MATCH($A7,$H$7:$H$193,1)+1,COLUMN($H7)))-INDIRECT(ADDRESS(ROW($H$6)+MATCH($A7,$H$7:$H$193,1),COLUMN($H7)))) -> 4.3663862e-07 | E7: =D7-$D$2-$D$3*B7 -> -4.6044609e-06 | G7: =Messdaten!P5 -> 0.118 | H7: =G7+$H$3 -> -4.412 | I7: =(J7-J$7)/J$7 -> 0 | J7: =Messdaten!O5 -> 7378.0938
A8: =Messdaten!B7 -> 0.04 | B8: =Messdaten!C7 -> 0 | C8: =Messdaten!D7 -> 0.011 | D8: =INDIRECT(ADDRESS(ROW($H$6)+MATCH($A8,$H$7:$H$193,1),COLUMN($H8)+1))+(INDIRECT(ADDRESS(ROW($H$6)+MATCH($A8,$H$7:$H$193,1)+1,COLUMN($H8)+1))-INDIRECT(ADDRESS(ROW($H$6)+MATCH($A8,$H$7:$H$193,1),COLUMN($H8)+1)))*($A8-INDIRECT(ADDRESS(ROW($H$6)+MATCH($A8,$H$7:$H$193,1),COLUMN($H8))))/(INDIRECT(ADDRESS(ROW($H$6)+MATCH($A8,$H$7:$H$193,1)+1,COLUMN($H8)))-INDIRECT(ADDRESS(ROW($H$6)+MATCH($A8,$H$7:$H$193,1),COLUMN($H8)))) -> 2.6835417e-07 | E8: =D8-$D$2-$D$3*B8 -> -4.7727453e-06 | G8: =Messdaten!P6 -> 0.29 | H8: =G8+$H$3 -> -4.24 | I8: =(J8-J$7)/J$7 -> 1.3282564e-07 | J8: =Messdaten!O6 -> 7378.0947
A9: =Messdaten!B8 -> 0.06 | B9: =Messdaten!C8 -> 0 | C9: =Messdaten!D8 -> 0.017 | D9: =INDIRECT(ADDRESS(ROW($H$6)+MATCH($A9,$H$7:$H$193,1),COLUMN($H9)+1))+(INDIRECT(ADDRESS(ROW($H$6)+MATCH($A9,$H$7:$H$193,1)+1,COLUMN($H9)+1))-INDIRECT(ADDRESS(ROW($H$6)+MATCH($A9,$H$7:$H$193,1),COLUMN($H9)+1)))*($A9-INDIRECT(ADDRESS(ROW($H$6)+MATCH($A9,$H$7:$H$193,1),COLUMN($H9))))/(INDIRECT(ADDRESS(ROW($H$6)+MATCH($A9,$H$7:$H$193,1)+1,COLUMN($H9)))-INDIRECT(ADDRESS(ROW($H$6)+MATCH($A9,$H$7:$H$193,1),COLUMN($H9)))) -> 1.0006971e-07 | E9: =D9-$D$2-$D$3*B9 -> -4.9410298e-06 | G9: =Messdaten!P7 -> 0.462 | H9: =G9+$H$3 -> -4.068 | I9: =(J9-J$7)/J$7 -> -9.2706873e-07 | J9: =Messdaten!O7 -> 7378.0869
A10: =Messdaten!B9 -> 0.08 | B10: =Messdaten!C9 -> 0 | C10: =Messdaten!D9 -> 0.011 | D10: =INDIRECT(ADDRESS(ROW($H$6)+MATCH($A10,$H$7:$H$193,1),COLUMN($H10)+1))+(INDIRECT(ADDRESS(ROW($H$6)+MATCH($A10,$H$7:$H$193,1)+1,COLUMN($H10)+1))-INDIRECT(ADDRESS(ROW($H$6)+MATCH($A10,$H$7:$H$193,1),COLUMN($H10)+1)))*($A10-INDIRECT(ADDRESS(ROW($H$6)+MATCH($A10,$H$7:$H$193,1),COLUMN($H10))))/(INDIRECT(ADDRESS(ROW($H$6)+MATCH($A10,$H$7:$H$193,1)+1,COLUMN($H10)))-INDIRECT(ADDRESS(ROW($H$6)+MATCH($A10,$H$7:$H$193,1),COLUMN($H10)))) -> -1.7364415e-07 | E10: =D10-$D$2-$D$3*B10 -> -5.2147436e-06 | G10: =Messdaten!P8 -> 0.634 | H10: =G10+$H$3 -> -3.896 | I10: =(J10-J$7)/J$7 -> -1.9191949e-06 | J10: =Messdaten!O8 -> 7378.0796
A11: =Messdaten!B10 -> 0.1 | B11: =Messdaten!C10 -> 0 | C11: =Messdaten!D10 -> 0.022 | D11: =INDIRECT(ADDRESS(ROW($H$6)+MATCH($A11,$H$7:$H$193,1),COLUMN($H11)+1))+(INDIRECT(ADDRESS(ROW($H$6)+MATCH($A11,$H$7:$H$193,1)+1,COLUMN($H11)+1))-INDIRECT(ADDRESS(ROW($H$6)+MATCH($A11,$H$7:$H$193,1),COLUMN($H11)+1)))*($A11-INDIRECT(ADDRESS(ROW($H$6)+MATCH($A11,$H$7:$H$193,1),COLUMN($H11))))/(INDIRECT(ADDRESS(ROW($H$6)+MATCH($A11,$H$7:$H$193,1)+1,COLUMN($H11)))-INDIRECT(ADDRESS(ROW($H$6)+MATCH($A11,$H$7:$H$193,1),COLUMN($H11)))) -> -4.7371535e-07 | E11: =D11-$D$2-$D$3*B11 -> -5.5148148e-06 | G11: =Messdaten!P9 -> 0.806 | H11: =G11+$H$3 -> -3.724 | I11: =(J11-J$7)/J$7 -> 5.9500464e-07 | J11: =Messdaten!O9 -> 7378.0981
A12: =Messdaten!B11 -> 0.12 | B12: =Messdaten!C11 -> 0 | C12: =Messdaten!D11 -> 0.017 | D12: =INDIRECT(ADDRESS(ROW($H$6)+MATCH($A12,$H$7:$H$193,1),COLUMN($H12)+1))+(INDIRECT(ADDRESS(ROW($H$6)+MATCH($A12,$H$7:$H$193,1)+1,COLUMN($H12)+1))-INDIRECT(ADDRESS(ROW($H$6)+MATCH($A12,$H$7:$H$193,1),COLUMN($H12)+1)))*($A12-INDIRECT(ADDRESS(ROW($H$6)+MATCH($A12,$H$7:$H$193,1),COLUMN($H12))))/(INDIRECT(ADDRESS(ROW($H$6)+MATCH($A12,$H$7:$H$193,1)+1,COLUMN($H12)))-INDIRECT(ADDRESS(ROW($H$6)+MATCH($A12,$H$7:$H$193,1),COLUMN($H12)))) -> -7.7378656e-07 | E12: =D12-$D$2-$D$3*B12 -> -5.814886e-06 | G12: =Messdaten!P10 -> 0.979 | H12: =G12+$H$3 -> -3.551 | I12: =(J12-J$7)/J$7 -> 1.1913646e-06 | J12: =Messdaten!O10 -> 7378.1025
A13: =Messdaten!B12 -> 0.14 | B13: =Messdaten!C12 -> 0 | C13: =Messdaten!D12 -> 0.011 | D13: =INDIRECT(ADDRESS(ROW($H$6)+MATCH($A13,$H$7:$H$193,1),COLUMN($H13)+1))+(INDIRECT(ADDRESS(ROW($H$6)+MATCH($A13,$H$7:$H$193,1)+1,COLUMN($H13)+1))-INDIRECT(ADDRESS(ROW($H$6)+MATCH($A13,$H$7:$H$193,1),COLUMN($H13)+1)))*($A13-INDIRECT(ADDRESS(ROW($H$6)+MATCH($A13,$H$7:$H$193,1),COLUMN($H13))))/(INDIRECT(ADDRESS(ROW($H$6)+MATCH($A13,$H$7:$H$193,1)+1,COLUMN($H13)))-INDIRECT(ADDRESS(ROW($H$6)+MATCH($A13,$H$7:$H$193,1),COLUMN($H13)))) -> -1.0738578e-06 | E13: =D13-$D$2-$D$3*B13 -> -6.1149572e-06 | G13: =Messdaten!P11 -> 1.151 | H13: =G13+$H$3 -> -3.379 | I13: =(J13-J$7)/J$7 -> 6.6412818e-08 | J13: =Messdaten!O11 -> 7378.0942
A14: =Messdaten!B13 -> 0.16 | B14: =Messdaten!C13 -> 0 | C14: =Messdaten!D13 -> 0.011 | D14: =INDIRECT(ADDRESS(ROW($H$6)+MATCH($A14,$H$7:$H$193,1),COLUMN($H14)+1))+(INDIRECT(ADDRESS(ROW($H$6)+MATCH($A14,$H$7:$H$193,1)+1,COLUMN($H14)+1))-INDIRECT(ADDRESS(ROW($H$6)+MATCH($A14,$H$7:$H$193,1),COLUMN($H14)+1)))*($A14-INDIRECT(ADDRESS(ROW($H$6)+MATCH($A14,$H$7:$H$193,1),COLUMN($H14))))/(INDIRECT(ADDRESS(ROW($H$6)+MATCH($A14,$H$7:$H$193,1)+1,COLUMN($H14)))-INDIRECT(ADDRESS(ROW($H$6)+MATCH($A14,$H$7:$H$193,1),COLUMN($H14)))) -> -1.373929e-06 | E14: =D14-$D$2-$D$3*B14 -> -6.4150284e-06 | G14: =Messdaten!P12 -> 1.323 | H14: =G14+$H$3 -> -3.207 | I14: =(J14-J$7)/J$7 -> -6.6412818e-08 | J14: =Messdaten!O12 -> 7378.0933
A15: =Messdaten!B14 -> 0.18 | B15: =Messdaten!C14 -> 0 | C15: =Messdaten!D14 -> 0.011 | D15: =INDIRECT(ADDRESS(ROW($H$6)+MATCH($A15,$H$7:$H$193,1),COLUMN($H15)+1))+(INDIRECT(ADDRESS(ROW($H$6)+MATCH($A15,$H$7:$H$193,1)+1,COLUMN($H15)+1))-INDIRECT(ADDRESS(ROW($H$6)+MATCH($A15,$H$7:$H$193,1),COLUMN($H15)+1)))*($A15-INDIRECT(ADDRESS(ROW($H$6)+MATCH($A15,$H$7:$H$193,1),COLUMN($H15))))/(INDIRECT(ADDRESS(ROW($H$6)+MATCH($A15,$H$7:$H$193,1)+1,COLUMN($H15)))-INDIRECT(ADDRESS(ROW($H$6)+MATCH($A15,$H$7:$H$193,1),COLUMN($H15)))) -> -1.6740002e-06 | E15: =D15-$D$2-$D$3*B15 -> -6.7150996e-06 | G15: =Messdaten!P13 -> 1.495 | H15: =G15+$H$3 -> -3.035 | I15: =(J15-J$7)/J$7 -> -1.3282564e-07 | J15: =Messdaten!O13 -> 7378.0928
